Workbook

Sheet RESUMEN
A1: ÁLBUM LaLiga - SEGUIMIENTO DE CROMOS
A2: Equipo | B2: Total Cromos | C2: Faltan | D2: Pedir | E2: Repetidos (total) | F2: Enviados
A3: D. ALAVÉS | B3: 27 | C3: =COUNTIF('D. ALAVÉS'!C3:C29,"") -> 8 | D3: =COUNTIF('D. ALAVÉS'!D3:D29,"X") -> 1 | E3: =SUMIF('D. ALAVÉS'!E3:E29,">"&0,'D. ALAVÉS'!E3:E29) -> 32 | F3: =SUM('D. ALAVÉS'!F3:F29) -> 0
A4: ATHLETIC CLUB | B4: 26 | C4: =COUNTIF('ATHLETIC CLUB'!C3:C28,"") -> 7 | D4: =COUNTIF('ATHLETIC CLUB'!D3:D28,"X") -> 1 | E4: =SUMIF('ATHLETIC CLUB'!E3:E28,">"&0,'ATHLETIC CLUB'!E3:E28) -> 19 | F4: =SUM('ATHLETIC CLUB'!F3:F28) -> 1
A5: ATLÉTICO DE MADRID | B5: 25 | C5: =COUNTIF('ATLÉTICO DE MADRID'!C3:C27,"") -> 8 | D5: =COUNTIF('ATLÉTICO DE MADRID'!D3:D27,"X") -> 4 | E5: =SUMIF('ATLÉTICO DE MADRID'!E3:E27,">"&0,'ATLÉTICO DE MADRID'!E3:E27) -> 19 | F5: =SUM('ATLÉTICO DE MADRID'!F3:F27) -> 1
A6: FC BARCELONA | B6: 25 | C6: =COUNTIF('FC BARCELONA'!C3:C27,"") -> 6 | D6: =COUNTIF('FC BARCELONA'!D3:D27,"X") -> 2 | E6: =SUMIF('FC BARCELONA'!E3:E27,">"&0,'FC BARCELONA'!E3:E27) -> 20 | F6: =SUM('FC BARCELONA'!F3:F27) -> 2
A7: REAL BETIS | B7: 28 | C7: =COUNTIF('REAL BETIS'!C3:C30,"") -> 12 | D7: =COUNTIF('REAL BETIS'!D3:D30,"X") -> 5 | E7: =SUMIF('REAL BETIS'!E3:E30,">"&0,'REAL BETIS'!E3:E30) -> 17 | F7: =SUM('REAL BETIS'!F3:F30) -> 0
A8: CADIZ CF | B8: 26 | C8: =COUNTIF('CADIZ CF'!C3:C28,"") -> 9 | D8: =COUNTIF('CADIZ CF'!D3:D28,"X") -> 3 | E8: =SUMIF('CADIZ CF'!E3:E28,">"&0,'CADIZ CF'!E3:E28) -> 13 | F8: =SUM('CADIZ CF'!F3:F28) -> 0
A9: RC CELTA | B9: 24 | C9: =COUNTIF('RC CELTA'!C3:C26,"") -> 5 | D9: =COUNTIF('RC CELTA'!D3:D26,"X") -> 1 | E9: =SUMIF('RC CELTA'!E3:E26,">"&0,'RC CELTA'!E3:E26) -> 20 | F9: =SUM('RC CELTA'!F3:F26) -> 0
A10: ELCHE CF | B10: 26 | C10: =COUNTIF('ELCHE CF'!C3:C28,"") -> 8 | D10: =COUNTIF('ELCHE CF'!D3:D28,"X") -> 3 | E10: =SUMIF('ELCHE CF'!E3:E28,">"&0,'ELCHE CF'!E3:E28) -> 16 | F10: =SUM('ELCHE CF'!F3:F28) -> 1
A11: RCD ESPANYOL | B11: 24 | C11: =COUNTIF('RCD ESPANYOL'!C3:C26,"") -> 7 | D11: =COUNTIF('RCD ESPANYOL'!D3:D26,"X") -> 4 | E11: =SUMIF('RCD ESPANYOL'!E3:E26,">"&0,'RCD ESPANYOL'!E3:E26) -> 19 | F11: =SUM('RCD ESPANYOL'!F3:F26) -> 1
A12: GETAFE CF | B12: 28 | C12: =COUNTIF('GETAFE CF'!C3:C30,"") -> 10 | D12: =COUNTIF('GETAFE CF'!D3:D30,"X") -> 3 | E12: =SUMIF('GETAFE CF'!E3:E30,">"&0,'GETAFE CF'!E3:E30) -> 22 | F12: =SUM('GETAFE CF'!F3:F30) -> 2
A13: GRANADA CF | B13: 24 | C13: =COUNTIF('GRANADA CF'!C3:C26,"") -> 6 | D13: =COUNTIF('GRANADA CF'!D3:D26,"X") -> 3 | E13: =SUMIF('GRANADA CF'!E3:E26,">"&0,'GRANADA CF'!E3:E26) -> 14 | F13: =SUM('GRANADA CF'!F3:F26) -> 0
A14: LEVANTE UD | B14: 25 | C14: =COUNTIF('LEVANTE UD'!C3:C27,"") -> 6 | D14: =COUNTIF('LEVANTE UD'!D3:D27,"X") -> 1 | E14: =SUMIF('LEVANTE UD'!E3:E27,">"&0,'LEVANTE UD'!E3:E27) -> 14 | F14: =SUM('LEVANTE UD'!F3:F27) -> 1
A15: REAL MADRID | B15: 27 | C15: =COUNTIF('REAL MADRID'!C3:C29,"") -> 9 | D15: =COUNTIF('REAL MADRID'!D3:D29,"X") -> 3 | E15: =SUMIF('REAL MADRID'!E3:E29,">"&0,'REAL MADRID'!E3:E29) -> 16 | F15: =SUM('REAL MADRID'!F3:F29) -> 4
A16: RCD MALLORCA | B16: 25 | C16: =COUNTIF('RCD MALLORCA'!C3:C27,"") -> 5 | D16: =COUNTIF('RCD MALLORCA'!D3:D27,"X") -> 0 | E16: =SUMIF('RCD MALLORCA'!E3:E27,">"&0,'RCD MALLORCA'!E3:E27) -> 5 | F16: =SUM('RCD MALLORCA'!F3:F27) -> 1
A17: C.A. OSASUNA | B17: 26 | C17: =COUNTIF('C.A. OSASUNA'!C3:C28,"") -> 7 | D17: =COUNTIF('C.A. OSASUNA'!D3:D28,"X") -> 1 | E17: =SUMIF('C.A. OSASUNA'!E3:E28,">"&0,'C.A. OSASUNA'!E3:E28) -> 15 | F17: =SUM('C.A. OSASUNA'!F3:F28) -> 0
A18: RAYO VALLECANO | B18: 26 | C18: =COUNTIF('RAYO VALLECANO'!C3:C28,"") -> 7 | D18: =COUNTIF('RAYO VALLECANO'!D3:D28,"X") -> 1 | E18: =SUMIF('RAYO VALLECANO'!E3:E28,">"&0,'RAYO VALLECANO'!E3:E28) -> 21 | F18: =SUM('RAYO VALLECANO'!F3:F28) -> 1
A19: REAL SOCIEDAD | B19: 25 | C19: =COUNTIF('REAL SOCIEDAD'!C3:C27,"") -> 8 | D19: =COUNTIF('REAL SOCIEDAD'!D3:D27,"X") -> 4 | E19: =SUMIF('REAL SOCIEDAD'!E3:E27,">"&0,'REAL SOCIEDAD'!E3:E27) -> 12 | F19: =SUM('REAL SOCIEDAD'!F3:F27) -> 0
A20: SEVILLA FC | B20: 24 | C20: =COUNTIF('SEVILLA FC'!C3:C26,"") -> 4 | D20: =COUNTIF('SEVILLA FC'!D3:D26,"X") -> 0 | E20: =SUMIF('SEVILLA FC'!E3:E26,">"&0,'SEVILLA FC'!E3:E26) -> 23 | F20: =SUM('SEVILLA FC'!F3:F26) -> 1
A21: VALENCIA CF | B21: 25 | C21: =COUNTIF('VALENCIA CF'!C3:C27,"") -> 8 | D21: =COUNTIF('VALENCIA CF'!D3:D27,"X") -> 3 | E21: =SUMIF('VALENCIA CF'!E3:E27,">"&0,'VALENCIA CF'!E3:E27) -> 21 | F21: =SUM('VALENCIA CF'!F3:F27) -> 7
A22: VILLARREAL CF | B22: 25 | C22: =COUNTIF('VILLARREAL CF'!C3:C27,"") -> 8 | D22: =COUNTIF('VILLARREAL CF'!D3:D27,"X") -> 3 | E22: =SUMIF('VILLARREAL CF'!E3:E27,">"&0,'VILLARREAL CF'!E3:E27) -> 6 | F22: =SUM('VILLARREAL CF'!F3:F27) -> 0
A23: LEYENDAS LaLiga | B23: 32 | C23: =COUNTIF('LEYENDAS LaLiga'!C3:C34,"") -> 4 | D23: =COUNTIF('LEYENDAS LaLiga'!D3:D34,"X") -> 4 | E23: =SUMIF('LEYENDAS LaLiga'!E3:E34,">"&0,'LEYENDAS LaLiga'!E3:E34) -> 35 | F23: =SUM('LEYENDAS LaLiga'!F3:F34) -> 5
A24: FICHAJES DE INVIERNO | B24: 66 | C24: =COUNTIF('FICHAJES DE INVIERNO'!C3:C68,"") -> 19 | D24: =COUNTIF('FICHAJES DE INVIERNO'!D3:D68,"X") -> 17 | E24: =SUMIF('FICHAJES DE INVIERNO'!E3:E68,">"&0,'FICHAJES DE INVIERNO'!E3:E68) -> 18 | F24: =SUM('FICHAJES DE INVIERNO'!F3:F68) -> 1
A25: 50 ANIVERSARIO | B25: 9 | C25: =COUNTIF('50 ANIVERSARIO'!C3:C11,"") -> 2 | D25: =COUNTIF('50 ANIVERSARIO'!D3:D11,"X") -> 2 | E25: =SUMIF('50 ANIVERSARIO'!E3:E11,">"&0,'50 ANIVERSARIO'!E3:E11) -> 13 | F25: =SUM('50 ANIVERSARIO'!F3:F11) -> 4
A26: CHICLE LIGA | B26: 60 | C26: =COUNTIF('CHICLE LIGA'!D3:D62,"") -> 30 | D26: =COUNTIF('CHICLE LIGA'!E3:E62,"X") -> 30 | E26: =SUMIF('CHICLE LIGA'!F3:F62,">"&0,'CHICLE LIGA'!F3:F62) -> 0 | F26: =SUM('CHICLE LIGA'!G3:G62) -> 0
A27: TOTAL | B27: =SUM(B3:B26) -> 678 | C27: =SUM(C3:C26) -> 203 | D27: =SUM(D3:D26) -> 99 | E27: =SUM(E3:E26) -> 410 | F27: =SUM(F3:F26) -> 33
A29: 📝 Instrucciones: En cada pestaña, pon una X en "Tengo" cuando tengas el cromo. Si está vacío = te falta. En "Repetidos" escribe cuántas copias extra tienes.

Sheet CHICLE LIGA
A1: CHICLE LIGA 2021-22 — SHOW & FUEGO
A2: Equipo | B2: Tipo | C2: Jugador | D2: Tengo | E2: Pedir | F2: Repetidos | G2: Enviados
A3: D. ALAVÉS | B3: ESCUDO | C3: Escudo D. ALAVÉS | E3: X | F3: 0
A4: D. ALAVÉS | B4: SHOW | C4: Luis Rioja | D4: X | F4: 0
A5: D. ALAVÉS | B5: FUEGO | C5: Edgar | D5: X | F5: 0
A6: ATHLETIC CLUB | B6: ESCUDO | C6: Escudo ATHLETIC CLUB | E6: X | F6: 0
A7: ATHLETIC CLUB | B7: SHOW | C7: Williams | E7: X | F7: 0
A8: ATHLETIC CLUB | B8: FUEGO | C8: Vencedor | E8: X | F8: 0
A9: ATLÉTICO DE MADRID | B9: ESCUDO | C9: Escudo ATLÉTICO DE MADRID | E9: X | F9: 0
A10: ATLÉTICO DE MADRID | B10: SHOW | C10: Luis Suárez | D10: X | F10: 0
A11: ATLÉTICO DE MADRID | B11: FUEGO | C11: Marcos Llorente | D11: X | F11: 0
A12: FC BARCELONA | B12: ESCUDO | C12: Escudo FC BARCELONA | D12: X | F12: 0
A13: FC BARCELONA | B13: SHOW | C13: De Jong | D13: X | F13: 0
A14: FC BARCELONA | B14: FUEGO | C14: Pedri | E14: X | F14: 0
A15: REAL BETIS | B15: ESCUDO | C15: Escudo REAL BETIS | D15: X | F15: 0
A16: REAL BETIS | B16: SHOW | C16: Canales | E16: X | F16: 0
A17: REAL BETIS | B17: FUEGO | C17: Álex Moreno | D17: X | F17: 0
A18: CADIZ CF | B18: ESCUDO | C18: Escudo CADIZ CF | D18: X | F18: 0
A19: CADIZ CF | B19: SHOW | C19: Ledesma | E19: X | F19: 0
A20: CADIZ CF | B20: FUEGO | C20: Salvi | D20: X | F20: 0
A21: RC CELTA | B21: ESCUDO | C21: Escudo RC CELTA | D21: X | F21: 0
A22: RC CELTA | B22: SHOW | C22: Iago Aspas | E22: X | F22: 0
A23: RC CELTA | B23: FUEGO | C23: Brais Méndez | D23: X | F23: 0
A24: ELCHE CF | B24: ESCUDO | C24: Escudo ELCHE CF | D24: X | F24: 0
A25: ELCHE CF | B25: SHOW | C25: Edgar Badía | D25: X | F25: 0
A26: ELCHE CF | B26: FUEGO | C26: Raúl Guti | E26: X | F26: 0
A27: RCD ESPANYOL | B27: ESCUDO | C27: Escudo RCD ESPANYOL | D27: X | F27: 0
A28: RCD ESPANYOL | B28: SHOW | C28: De Tomás | D28: X | F28: 0
A29: RCD ESPANYOL | B29: FUEGO | C29: Puado | D29: X | F29: 0
A30: GETAFE CF | B30: ESCUDO | C30: Escudo GETAFE CF | E30: X | F30: 0
A31: GETAFE CF | B31: SHOW | C31: Maksimovic | D31: X | F31: 0
A32: GETAFE CF | B32: FUEGO | C32: Cucurella | E32: X | F32: 0
A33: GRANADA CF | B33: ESCUDO | C33: Escudo GRANADA CF | D33: X | F33: 0
A34: GRANADA CF | B34: SHOW | C34: Soldado | E34: X | F34: 0
A35: GRANADA CF | B35: FUEGO | C35: Luis Suárez | D35: X | F35: 0
A36: LEVANTE UD | B36: ESCUDO | C36: Escudo LEVANTE UD | D36: X | F36: 0
A37: LEVANTE UD | B37: SHOW | C37: Campaña | D37: X | F37: 0
A38: LEVANTE UD | B38: FUEGO | C38: Cárdenas | E38: X | F38: 0
A39: REAL MADRID | B39: ESCUDO | C39: Escudo REAL MADRID | D39: X | F39: 0
A40: REAL MADRID | B40: SHOW | C40: Benzema | E40: X | F40: 0
...

Sheet D. ALAVÉS
A1: D. ALAVÉS
A2: Nº | B2: Jugador / Cromo | C2: Tengo | D2: Pedir | E2: Repetidos | F2: Enviados
A3: 001 | B3: Escudo Alavés | C3: X | E3: 2
A4: 002 | B4: Entrenador - Javi Calleja | C4: X | E4: 2
A5: 003 | B5: Fernando Pacheco | D5: X
A6: 004 | B6: Rookie Impact Tachi | C6: X
A7: 005 | B7: Fernando Pacheco | C7: X | E7: 3
A8: 006 | B8: Sivera | C8: X | E8: 1
A9: 007 | B9: Martín | C9: X | E9: 2
A10: 008 | B10: Ximo Navarro | C10: X
A11: 009 | B11: Laguardia | C11: X
A12: 010 | B12: Lejeune (10A) | C12: X | E12: 3
A13: 011 | B13: Tachi (10B) | E13: 2
A14: 012 | B14: Rodrigo Ely | E14: 2
A15: 013 | B15: Duarte (12A) | C15: X
A16: 014 | B16: Iván Martín (12B) | E16: 3
A17: 015 | B17: Pere Pons | C17: X | E17: 3
A18: 016 | B18: Battaglia
A19: 017 | B19: Pina | C19: X
A20: 018 | B20: Luis Rioja | C20: X | E20: 1
A21: 019 | B21: Borja Sainz | E21: 2
A22: 020 | B22: Edgar | C22: X
A23: 021 | B23: Joselu | C23: X | E23: 2
A24: 022 | B24: Lucas Pérez
A25: 023 | B25: Javi López (11BIS) | C25: X | E25: 2
A26: 024 | B26: Toni Moya (14BIS) | C26: X | E26: 2
A27: 025 | B27: Pellistri (17BIS) | C27: X
A28: 026 | B28: Guidetti (20BIS) | C28: X
A29: 027 | B29: Miguel De la Fuente (18BIS)

Sheet ATHLETIC CLUB
A1: ATHLETIC CLUB
A2: Nº | B2: Jugador / Cromo | C2: Tengo | D2: Pedir | E2: Repetidos | F2: Enviados
A3: 041 | B3: Escudo Athletic Club | C3: X
A4: 042 | B4: Entrenador - Marcelino García | C4: X | E4: 2
A5: 043 | B5: Williams | D5: X
A6: 044 | B6: Rookie Impact Nico Williams | C6: X | E6: 1
A7: 045 | B7: Unai Simón | C7: X
A8: 046 | B8: Ezkieta
A9: 047 | B9: Capa
A10: 048 | B10: De Marcos (8A) | C10: X
A11: 049 | B11: Nuñez (8B) | E11: 2
A12: 050 | B12: Yeray | C12: X | E12: 1
A13: 051 | B13: Íñigo Martínez | C13: X
A14: 052 | B14: Yuri (11A) | C14: X | E14: 1
A15: 053 | B15: Balenziaga (11B) | E15: 1 | F15: 1
A16: 054 | B16: Dani García | C16: X | E16: 2
A17: 055 | B17: Vesga | C17: X | E17: 1
A18: 056 | B18: Vencedor | C18: X | E18: 3
A19: 057 | B19: Sancet | C19: X | E19: 1
A20: 058 | B20: Raúl García | C20: X | E20: 3
A21: 059 | B21: Muniain | C21: X
A22: 060 | B22: Berenguer | C22: X
A23: 061 | B23: Villalibre (19A) | C23: X
A24: 062 | B24: Morcillo (19B)
A25: 063 | B25: Williams | C25: X | E25: 1
A26: 064 | B26: Aguirrezabala (6BIS) | C26: X
A27: 065 | B27: Lekue (7BIS) | C27: X
A28: 066 | B28: Vivian (9BIS)

Sheet ATLÉTICO DE MADRID
A1: ATLÉTICO DE MADRID
A2: Nº | B2: Jugador / Cromo | C2: Tengo | D2: Pedir | E2: Repetidos | F2: Enviados
A3: 071 | B3: Escudo Atlético de Madrid | C3: X
A4: 072 | B4: Entrenador - Diego Pablo Simeone | C4: X | E4: 3
A5: 073 | B5: Marcos Llorente | D5: X
A6: 074 | B6: Rookie Impact Camello | C6: X | E6: 1
A7: 075 | B7: Oblak | C7: X | E7: 2
A8: 076 | B8: Grbic | E8: 1
A9: 077 | B9: Trippier (7A)
A10: 078 | B10: Vrsaljko (7B) | C10: X
A11: 079 | B11: Giménez | C11: X | E11: 3 | F11: 1
A12: 080 | B12: Felipe | C12: X | E12: 1
A13: 081 | B13: Savic | D13: X
A14: 082 | B14: Mario Hermoso (11A) | C14: X | E14: 1
A15: 083 | B15: Lodi (11B) | E15: 2
A16: 084 | B16: Koke | C16: X
A17: 085 | B17: Kondogbia (13A) | C17: X
A18: 086 | B18: Herrera (13B)
A19: 087 | B19: Saúl | C19: X | E19: 1
A20: 088 | B20: Lemar | C20: X | E20: 1
A21: 089 | B21: Carrasco | C21: X | E21: 1
A22: 090 | B22: Joao Félix | C22: X | E22: 2
A23: 091 | B23: Marcos Llorente | D23: X
A24: 092 | B24: Correa | C24: X
A25: 093 | B25: Luis Suárez | C25: X
A26: 094 | B26: Lecomte (6BIS) | C26: X
A27: 095 | B27: Matheus Cunha (14BIS) | D27: X

Sheet FC BARCELONA
A1: FC BARCELONA
A2: Nº | B2: Jugador / Cromo | C2: Tengo | D2: Pedir | E2: Repetidos | F2: Enviados
A3: 101 | B3: Escudo FC Barcelona | C3: X
A4: 102 | B4: Entrenador - Ronald Koeman | C4: X | E4: 2
A5: 103 | B5: Messi | C5: X
A6: 104 | B6: Rookie Impact Ilaix Moriba | C6: X | E6: 3
A7: 105 | B7: Ter Stegen | C7: X | E7: 1
A8: 106 | B8: Neto | C8: X | E8: 1
A9: 107 | B9: Dest (7A) | C9: X | E9: 1
A10: 108 | B10: Sergi Roberto (7B)
A11: 109 | B11: Piqué | C11: X | E11: 1
A12: 110 | B12: Araújo | D12: X
A13: 111 | B13: Mingueza | C13: X
A14: 112 | B14: Lenglet | C14: X
A15: 113 | B15: Jordi Alba | C15: X
A16: 114 | B16: Sergio Busquets | C16: X | E16: 1 | F16: 1
A17: 115 | B17: De Jong | D17: X
A18: 116 | B18: Ilaix Moriba (15A) | C18: X
A19: 117 | B19: Riqui Puig (15B)
A20: 118 | B20: Pedri | C20: X | E20: 2
A21: 119 | B21: Messi | C21: X
A22: 120 | B22: Ansu Fati | C22: X | E22: 3
A23: 121 | B23: Griezmann | C23: X
A24: 122 | B24: Dembélé (20A) | E24: 2 | F24: 1
A25: 123 | B25: Braithwaite (20B) | C25: X | E25: 3
A26: 124 | B26: Yusuf Demir (17BIS) | C26: X
A27: 125 | B27: Coutinho (19BIS)

Sheet REAL BETIS
A1: REAL BETIS
A2: Nº | B2: Jugador / Cromo | C2: Tengo | D2: Pedir | E2: Repetidos | F2: Enviados
A3: 131 | B3: Escudo Real Betis | D3: X
A4: 132 | B4: Entrenador - Manuel Pellegrini | C4: X | E4: 1
A5: 133 | B5: Canales | D5: X
A6: 134 | B6: Rookie Impact Rodri | D6: X
A7: 135 | B7: Bravo | C7: X | E7: 1
A8: 136 | B8: Joel
A9: 137 | B9: Montoya | C9: X | E9: 3
A10: 138 | B10: Sidnei
A11: 139 | B11: Víctor Ruiz | C11: X
A12: 140 | B12: Bartra | C12: X | E12: 1
A13: 141 | B13: Miranda (11A)
A14: 142 | B14: Álex Moreno (11B) | C14: X | E14: 2
A15: 143 | B15: Guido Rodríguez | C15: X
A16: 144 | B16: Aitor Ruibal (13A) | E16: 2
A17: 145 | B17: Guardado (13B) | C17: X
A18: 146 | B18: Canales | D18: X
A19: 147 | B19: Fekir | D19: X
A20: 148 | B20: Joaquín | C20: X | E20: 1
A21: 149 | B21: Tello | C21: X | E21: 1
A22: 150 | B22: Diego Lainez | C22: X | E22: 1
A23: 151 | B23: Juanmi (19A) | C23: X | E23: 1
A24: 152 | B24: Loren (19B) | E24: 2
A25: 153 | B25: Borja Iglesias | C25: X
A26: 154 | B26: Rui Silva (6BIS) | C26: X
A27: 155 | B27: Camarasa (12BIS) | E27: 1
A28: 156 | B28: Edgar (8BIS) | C28: X
A29: 157 | B29: Rodri (15BIS) | C29: X
A30: 158 | B30: William Carvalho (16BIS)

Sheet CADIZ CF
A1: CADIZ CF
A2: Nº | B2: Jugador / Cromo | C2: Tengo | D2: Pedir | E2: Repetidos | F2: Enviados
A3: 161 | B3: Escudo Cádiz CF | C3: X | E3: 3
A4: 162 | B4: Entrenador - Álvaro Cervera | C4: X
A5: 163 | B5: Ledesma | D5: X
A6: 164 | B6: Rookie Impact Bastida | D6: X
A7: 165 | B7: Ledesma | C7: X
A8: 166 | B8: David Gil | C8: X
A9: 167 | B9: Carcelén (7A) | C9: X
A10: 168 | B10: Akapo (7B) | E10: 1
A11: 169 | B11: Marcos Mauro | E11: 1
A12: 170 | B12: Fali | D12: X
A13: 171 | B13: Cala | C13: X | E13: 2
A14: 172 | B14: Espino | C14: X
A15: 173 | B15: José Mari | C15: X
A16: 174 | B16: Jonsson | C16: X
A17: 175 | B17: Álex Fernández | C17: X
A18: 176 | B18: Garrido (15A) | E18: 1
A19: 177 | B19: Iván Alejo (15B) | C19: X | E19: 2
A20: 178 | B20: Perea | E20: 1
A21: 179 | B21: Jairo | C21: X
A22: 180 | B22: Salvi | C22: X
A23: 181 | B23: Lozano | C23: X
A24: 182 | B24: Negredo | C24: X | E24: 1
A25: 183 | B25: Osmajic (17BIS) | E25: 1
A26: 184 | B26: Chust (8BIS) | C26: X
A27: 185 | B27: Álvaro Jiménez (16BIS) | C27: X
A28: 186 | B28: Sobrino (19BIS)

Sheet RC CELTA
A1: RC CELTA
A2: Nº | B2: Jugador / Cromo | C2: Tengo | D2: Pedir | E2: Repetidos | F2: Enviados
A3: 191 | B3: Escudo RC Celta | C3: X
A4: 192 | B4: Entrenador - Eduardo Coudet | C4: X
A5: 193 | B5: Iago Aspas | C5: X | E5: 3
A6: 194 | B6: Rookie Impact Fontán | C6: X
A7: 195 | B7: Rubén | C7: X
A8: 196 | B8: Iván Villar | E8: 1
A9: 197 | B9: Hugo Mallo | C9: X | E9: 3
A10: 198 | B10: Aidoo (8A) | C10: X | E10: 3
A11: 199 | B11: Fontán (8B) | E11: 1
A12: 200 | B12: Murillo | C12: X | E12: 1
A13: 201 | B13: Araújo | C13: X
A14: 202 | B14: Aarón (11A) | C14: X
A15: 203 | B15: Kevin (11B) | E15: 1
A16: 204 | B16: Tapia | C16: X
A17: 205 | B17: Solari | C17: X | E17: 2
A18: 206 | B18: Brais Méndez | D18: X
A19: 207 | B19: Fran Beltrán | C19: X | E19: 2
A20: 208 | B20: Denis Suárez | C20: X
A21: 209 | B21: Baeza | C21: X | E21: 2
A22: 210 | B22: Nolito | C22: X
A23: 211 | B23: Santi Mina | C23: X
A24: 212 | B24: Iago Aspas | C24: X | E24: 1
A25: 213 | B25: Dituro (6BIS) | C25: X
A26: 214 | B26: Galán (9BIS)

Sheet ELCHE CF
A1: ELCHE CF
A2: Nº | B2: Jugador / Cromo | C2: Tengo | D2: Pedir | E2: Repetidos | F2: Enviados
A3: 221 | B3: Escudo Elche CF | C3: X
A4: 222 | B4: Entrenador - Fran Escribá | C4: X
A5: 223 | B5: Marcone | C5: X | E5: 1 | F5: 1
A6: 224 | B6: Rookie Impact Raúl Guti | C6: X
A7: 225 | B7: Edgar Badía | C7: X
A8: 226 | B8: Casilla | C8: X | E8: 2
A9: 227 | B9: Barragán | C9: X
A10: 228 | B10: Dani Calvo | E10: 2
A11: 229 | B11: Diego González (9A) | E11: 1
A12: 230 | B12: Palacios (9B) | C12: X | E12: 1
A13: 231 | B13: Josema | C13: X
A14: 232 | B14: Gonzalo Verdú | C14: X | E14: 1
A15: 233 | B15: Mójica | C15: X | E15: 1
A16: 234 | B16: Josan (13A) | C16: X
A17: 235 | B17: Mfulu (13B) | E17: 2
A18: 236 | B18: Fidel | D18: X
A19: 237 | B19: Marcone | C19: X | E19: 2
A20: 238 | B20: Raúl Guti | C20: X | E20: 1
A21: 239 | B21: Morente | D21: X
A22: 240 | B22: Pere Milla | C22: X
A23: 241 | B23: Boyé | C23: X | E23: 2
A24: 242 | B24: Piatti (20A)
A25: 243 | B25: Carrillo (20B) | C25: X
A26: 244 | B26: Bigas (8BIS) | C26: X
A27: 245 | B27: Mascarell (14BIS) | D27: X
A28: 246 | B28: Gumbau (15BIS)

Sheet RCD ESPANYOL
A1: RCD ESPANYOL
A2: Nº | B2: Jugador / Cromo | C2: Tengo | D2: Pedir | E2: Repetidos | F2: Enviados
A3: 251 | B3: Escudo RCD Espanyol | C3: X | E3: 1
A4: 252 | B4: Entrenador - Vicente Moreno | C4: X | E4: 2
A5: 253 | B5: De Tomás | C5: X | E5: 2
A6: 254 | B6: Rookie Impact Nico Melamed | C6: X
A7: 255 | B7: Diego López | C7: X | E7: 1
A8: 256 | B8: Oier | C8: X
A9: 257 | B9: Miguelón | C9: X | E9: 1
A10: 258 | B10: Óscar Gil | C10: X
A11: 259 | B11: Cabrera | C11: X | E11: 1
A12: 260 | B12: Calero | C12: X | E12: 2
A13: 261 | B13: David López | D13: X
A14: 262 | B14: Pedrosa (12A) | C14: X | E14: 1
A15: 263 | B15: Dídac (12B)
A16: 264 | B16: Keidi Bare | D16: X
A17: 265 | B17: Melendo (14A) | E17: 1
A18: 266 | B18: Fran Mérida (14B) | C18: X
A19: 267 | B19: Darder | C19: X | E19: 1
A20: 268 | B20: Embarba | D20: X
A21: 269 | B21: Nico Melamed | C21: X
A22: 270 | B22: Puado | C22: X | E22: 3
A23: 271 | B23: Dimata (19A) | C23: X | E23: 1 | F23: 1
A24: 272 | B24: Wu Lei (19B)
A25: 273 | B25: De Tomás | C25: X | E25: 2
A26: 274 | B26: Aleix Vidal (13BIS) | D26: X

Sheet GETAFE CF
A1: GETAFE CF
A2: Nº | B2: Jugador / Cromo | C2: Tengo | D2: Pedir | E2: Repetidos | F2: Enviados
A3: 281 | B3: Escudo Getafe CF | D3: X
A4: 282 | B4: Míchel | C4: X | E4: 1
A5: 283 | B5: Cucurella | D5: X
A6: 284 | B6: Rookie Impact Iglesias | C6: X
A7: 285 | B7: David Soria | C7: X | E7: 2
A8: 286 | B8: Yáñez | C8: X | E8: 1
A9: 287 | B9: Nyom (7A) | C9: X | E9: 2
A10: 288 | B10: Iglesias (7B)
A11: 289 | B11: Damián Suárez | C11: X | E11: 1
A12: 290 | B12: Chema | C12: X | E12: 2
A13: 291 | B13: Djené | C13: X
A14: 292 | B14: Cabaco | C14: X | E14: 1
A15: 293 | B15: Olivera | C15: X | E15: 3
A16: 294 | B16: Arambarri (13A)
A17: 295 | B17: Timor (13B) | C17: X
A18: 296 | B18: Cucurella
A19: 297 | B19: Maksimovic | C19: X | E19: 2
A20: 298 | B20: Aleñá | C20: X
A21: 299 | B21: Hugo Duro | C21: X | E21: 1
A22: 300 | B22: Poveda | E22: 2
A23: 301 | B23: Mata | C23: X
A24: 302 | B24: Ünal | C24: X
A25: 303 | B25: Mitrovic (9BIS) | E25: 2
A26: 304 | B26: Jantko (14BIS) | C26: X
A27: 305 | B27: Sandro (18BIS) | C27: X | E27: 1 | F27: 1
A28: 306 | B28: Cuenca (11BIS) | E28: 1 | F28: 1
A29: 307 | B29: Jonathan Silva (12BIS)
A30: 308 | B30: Florentino Luis (17BIS) | D30: X

Sheet GRANADA CF
A1: GRANADA CF
A2: Nº | B2: Jugador / Cromo | C2: Tengo | D2: Pedir | E2: Repetidos | F2: Enviados
A3: 311 | B3: Escudo Granada CF | C3: X | E3: 2
A4: 312 | B4: Entrenador - Robert Moreno | C4: X
A5: 313 | B5: Machís | C5: X
A6: 314 | B6: Rookie Impact Soro | C6: X
A7: 315 | B7: Luis Maximiano | C7: X
A8: 316 | B8: Aarón | C8: X | E8: 2
A9: 317 | B9: Foulquier | C9: X | E9: 1
A10: 318 | B10: Víctor Díaz (8A)
A11: 319 | B11: Quni (8B) | C11: X | E11: 2
A12: 320 | B12: Germán | C12: X
A13: 321 | B13: Domingos Duarte | C13: X | E13: 1
A14: 322 | B14: Neva | C14: X | E14: 1
A15: 323 | B15: Monchu | C15: X | E15: 1
A16: 324 | B16: Gonalons | C16: X
A17: 325 | B17: Montoro | C17: X
A18: 326 | B18: Soro (15A) | E18: 2
A19: 327 | B19: Yan Eteki (15B) | C19: X
A20: 328 | B20: Milla | C20: X
A21: 329 | B21: Machís | D21: X
A22: 330 | B22: Puertas | C22: X
A23: 331 | B23: Jorge Molina | C23: X | E23: 2
A24: 332 | B24: Luis Suárez | D24: X
A25: 333 | B25: Abram (10BIS)
A26: 334 | B26: Arias (7BIS) | D26: X

Sheet LEVANTE UD
A1: LEVANTE UD
A2: Nº | B2: Jugador / Cromo | C2: Tengo | D2: Pedir | E2: Repetidos | F2: Enviados
A3: 341 | B3: Escudo Levante UD | C3: X | E3: 1
A4: 342 | B4: Entrenador - Paco López | C4: X
A5: 343 | B5: Roger | C5: X | E5: 1
A6: 344 | B6: Rookie Impact Cárdenas | C6: X | E6: 1
A7: 345 | B7: Aitor Fernández | C7: X | E7: 1
A8: 346 | B8: Cárdenas | C8: X | E8: 1
A9: 347 | B9: Miramón (7A) | C9: X
A10: 348 | B10: Son (7B)
A11: 349 | B11: Óscar Duarte | C11: X
A12: 350 | B12: Postigo | C12: X | E12: 2 | F12: 1
A13: 351 | B13: Rúben Vezo (10A) | C13: X | E13: 1
A14: 352 | B14: Róber (10B)
A15: 353 | B15: Clerc | C15: X | E15: 2
A16: 354 | B16: Radoja (12A)
A17: 355 | B17: Malsa (12B) | C17: X
A18: 356 | B18: Melero | C18: X
A19: 357 | B19: Campaña | C19: X | E19: 1
A20: 358 | B20: Vukcevic | C20: X | E20: 1
A21: 359 | B21: Bardhi | C21: X | E21: 1
A22: 360 | B22: De Frutos | C22: X
A23: 361 | B23: Morales | C23: X | E23: 1
A24: 362 | B24: Dani Gómez | C24: X
A25: 363 | B25: Roger | D25: X
A26: 364 | B26: Franquesa (11BIS)
A27: 365 | B27: Pablo Martínez (15BIS)

Sheet REAL MADRID
A1: REAL MADRID
A2: Nº | B2: Jugador / Cromo | C2: Tengo | D2: Pedir | E2: Repetidos | F2: Enviados
A3: 371 | B3: Escudo Real Madrid | D3: X
A4: 372 | B4: Carlo Ancelotti | C4: X | E4: 2
A5: 373 | B5: Benzema | C5: X
A6: 374 | B6: Rookie Impact Blanco | C6: X
A7: 375 | B7: Courtois | C7: X
A8: 376 | B8: Lunin | C8: X | E8: 1
A9: 377 | B9: Carvajal | C9: X
A10: 378 | B10: Odriozola | D10: X
A11: 379 | B11: Nacho | C11: X
A12: 380 | B12: Varane
A13: 381 | B13: Militao | C13: X
A14: 382 | B14: Mendy (12A) | E14: 2
A15: 383 | B15: Marcelo (12B) | C15: X | E15: 1 | F15: 1
A16: 384 | B16: Casemiro | C16: X | E16: 1 | F16: 1
A17: 385 | B17: Kroos | C17: X | E17: 2 | F17: 1
A18: 386 | B18: Modric | C18: X | E18: 2
A19: 387 | B19: Fede Valverde (16A) | C19: X | E19: 2 | F19: 1
A20: 388 | B20: Lucas Vázquez (16B) | E20: 2
A21: 389 | B21: Marco Asensio (17A) | C21: X | E21: 1
A22: 390 | B22: Isco (17B)
A23: 391 | B23: Hazard (18A)
A24: 392 | B24: Rodrygo (18B) | C24: X
A25: 393 | B25: Benzema | C25: X
A26: 394 | B26: Vinícius | C26: X
A27: 395 | B27: Miguel Gutiérrez (10BIS) | C27: X
A28: 396 | B28: Bale (14BIS)
A29: 397 | B29: Blanco (8BIS) | D29: X

Sheet RCD MALLORCA
A1: RCD MALLORCA
A2: Nº | B2: Jugador / Cromo | C2: Tengo | D2: Pedir | E2: Repetidos | F2: Enviados
A3: 401 | B3: Escudo RCD Mallorca | C3: X
A4: 402 | B4: Entrenador - Luis García | C4: X
A5: 403 | B5: Abdón | C5: X
A6: 404 | B6: Rookie Impact Luka Romero | C6: X | E6: 1
A7: 405 | B7: Reina | C7: X
A8: 406 | B8: Greif | C8: X
A9: 407 | B9: Sastre | C9: X
A10: 408 | B10: Valjent | C10: X
A11: 409 | B11: Raíllo | C11: X | E11: 1
A12: 410 | B12: Russo (10A) | C12: X
A13: 411 | B13: Sedlar (10B)
A14: 412 | B14: Oliván | C14: X
A15: 413 | B15: Cufré
A16: 414 | B16: Ruiz de Galarreta | C16: X
A17: 415 | B17: Baba (14A) | C17: X | E17: 1
A18: 416 | B18: Febas (14B)
A19: 417 | B19: Salva Sevilla | C19: X
A20: 418 | B20: Antonio Sánchez (16A)
A21: 419 | B21: Mollejo (16B) | C21: X | E21: 1 | F21: 1
A22: 420 | B22: Dani Rodríguez | C22: X | E22: 1
A23: 421 | B23: Lago Junior
A24: 422 | B24: Abdón | C24: X
A25: 423 | B25: Amath | C25: X
A26: 424 | B26: Battaglia (12BIS) | C26: X
A27: 425 | B27: Mboula (18BIS) | C27: X

Sheet C.A. OSASUNA
A1: C.A. OSASUNA
A2: Nº | B2: Jugador / Cromo | C2: Tengo | D2: Pedir | E2: Repetidos | F2: Enviados
A3: 431 | B3: Escudo CA Osasuna | C3: X | E3: 5
A4: 432 | B4: Entrenador - Jagoba Arrasate | C4: X
A5: 433 | B5: Rubén García | C5: X | E5: 1
A6: 434 | B6: Rookie Impact Javi Martínez | C6: X | E6: 1
A7: 435 | B7: Sergio Herrera | C7: X | E7: 1
A8: 436 | B8: Juan Pérez | C8: X
A9: 437 | B9: Nacho Vidal | C9: X | E9: 1
A10: 438 | B10: Ramalho (8A)
A11: 439 | B11: Unai García (8B) | C11: X
A12: 440 | B12: Aridane | C12: X
A13: 441 | B13: David García | C13: X
A14: 442 | B14: Juan Cruz
A15: 443 | B15: Oier | D15: X
A16: 444 | B16: Brasanac (13A) | C16: X | E16: 2
A17: 445 | B17: Javi Martínez (13B) | E17: 1
A18: 446 | B18: Moncayola | C18: X
A19: 447 | B19: Torró (15A) | C19: X
A20: 448 | B20: Íñigo Pérez (15B)
A21: 449 | B21: Roberto Torres | C21: X
A22: 450 | B22: Rubén García | C22: X
A23: 451 | B23: Jony (18A) | C23: X | E23: 2
A24: 452 | B24: Kike barja (18B)
A25: 453 | B25: Chimy Ávila | C25: X | E25: 1
A26: 454 | B26: Budimir | C26: X
A27: 455 | B27: José Ángel (10BIS)
A28: 456 | B28: Manu Sánchez (11BIS) | C28: X

Sheet RAYO VALLECANO
A1: RAYO VALLECANO
A2: Nº | B2: Jugador / Cromo | C2: Tengo | D2: Pedir | E2: Repetidos | F2: Enviados
A3: 461 | B3: Escudo Rayo Vallecano | D3: X
A4: 462 | B4: Entrenador - Andoni Iraola | C4: X
A5: 463 | B5: Isi | C5: X | E5: 2 | F5: 1
A6: 464 | B6: Rookie Impact Fran García | C6: X | E6: 1
A7: 465 | B7: Dimitrievski | C7: X
A8: 466 | B8: Luca Zidane | C8: X
A9: 467 | B9: Advíncula | E9: 1
A10: 468 | B10: Mario Hernández (8A) | C10: X | E10: 2
A11: 469 | B11: Velázquez (8B)
A12: 470 | B12: Catena | C12: X | E12: 3
A13: 471 | B13: Saveljich | C13: X | E13: 1
A14: 472 | B14: Fran García | C14: X | E14: 2
A15: 473 | B15: Santi Comesaña | C15: X
A16: 474 | B16: Mario Suárez (13A) | C16: X | E16: 2
A17: 475 | B17: Pozo (13B) | E17: 1
A18: 476 | B18: Óscar Valentín | C18: X
A19: 477 | B19: Trejo | C19: X | E19: 1
A20: 478 | B20: Isi | C20: X | E20: 1
A21: 479 | B21: Bebé | C21: X | E21: 1
A22: 480 | B22: Álvaro García | C22: X
A23: 481 | B23: Qasmi | C23: X
A24: 482 | B24: Andrés Martín | C24: X | E24: 1
A25: 483 | B25: Balliu (7BIS) | C25: X | E25: 1
A26: 484 | B26: Kevin Rodrigues (11BIS) | E26: 1
A27: 485 | B27: Unai López (16BIS)
A28: 486 | B28: Sergi Guardiola (20BIS)

Sheet REAL SOCIEDAD
A1: REAL SOCIEDAD
A2: Nº | B2: Jugador / Cromo | C2: Tengo | D2: Pedir | E2: Repetidos | F2: Enviados
A3: 491 | B3: Escudo Real Sociedad | C3: X | E3: 1
A4: 492 | B4: Entrenador - Imanol Alguacil | C4: X | E4: 2
A5: 493 | B5: Isak | C5: X
A6: 494 | B6: Rookie Impact Karrikaburu | C6: X | E6: 2
A7: 495 | B7: Remiro | C7: X
A8: 496 | B8: Ryan | C8: X
A9: 497 | B9: Gorosabel (7A) | C9: X | E9: 1
A10: 498 | B10: Zaldúa (7B)
A11: 499 | B11: Le Normand | C11: X | E11: 1
A12: 500 | B12: Aritz Elustondo | C12: X
A13: 501 | B13: Zubeldia | D13: X
A14: 502 | B14: Nacho Monreal | D14: X
A15: 503 | B15: Zubimendi (12A)
A16: 504 | B16: Illarramendi (12B) | C16: X
A17: 505 | B17: Guevara | D17: X
A18: 506 | B18: Mikel Merino | C18: X
A19: 507 | B19: Silva (15A) | C19: X
A20: 508 | B20: Guridi (15B) | E20: 3
A21: 509 | B21: Oyarzabal | C21: X | E21: 2
A22: 510 | B22: Barrenetxea | C22: X
A23: 511 | B23: Portu | C23: X
A24: 512 | B24: Januzaj (19A) | C24: X
A25: 513 | B25: Carlos Fernández (19B)
A26: 514 | B26: Isak | D26: X
A27: 515 | B27: Ahien Muñoz (11BIS) | C27: X

Sheet SEVILLA FC
A1: SEVILLA FC
A2: Nº | B2: Jugador / Cromo | C2: Tengo | D2: Pedir | E2: Repetidos | F2: Enviados
A3: 521 | B3: Escudo Sevilla FC | C3: X | E3: 3
A4: 522 | B4: Entrenador - Julen Lopetegui | C4: X | E4: 2
A5: 523 | B5: Jordán | C5: X | F5: 1
A6: 524 | B6: Rookie Impact Iván Romero | C6: X | E6: 1
A7: 525 | B7: Bounou | C7: X
A8: 526 | B8: Dmitrovic | C8: X
A9: 527 | B9: Jesús Navas | C9: X | E9: 4
A10: 528 | B10: Diego Carlos | C10: X
A11: 529 | B11: Koundé | C11: X | E11: 1
A12: 530 | B12: Sergi Gómez
A13: 531 | B13: Acuña | C13: X
A14: 532 | B14: Gudelj | C14: X | E14: 1
A15: 533 | B15: Fernando | C15: X
A16: 534 | B16: Jordán | C16: X | E16: 1
A17: 535 | B17: Rakitic | C17: X | E17: 1
A18: 536 | B18: Óliver (16A)
A19: 537 | B19: Óscar Rodríguez (16B) | C19: X | E19: 2
A20: 538 | B20: Papu Gómez | C20: X
A21: 539 | B21: Ocampos | C21: X | E21: 1
A22: 540 | B22: Suso (19A) | C22: X | E22: 2
A23: 541 | B23: Munir (19B) | E23: 1
A24: 542 | B24: En-Nesyri (20A) | C24: X | E24: 1
A25: 543 | B25: De Jong (20B) | E25: 2
A26: 544 | B26: Rekik (10BIS) | C26: X

Sheet VALENCIA CF
A1: VALENCIA CF
A2: Nº | B2: Jugador / Cromo | C2: Tengo | D2: Pedir | E2: Repetidos | F2: Enviados
A3: 551 | B3: Escudo Valencia CF | D3: X
A4: 552 | B4: Entrenador - José Bordalás | D4: X
A5: 553 | B5: Gayà | C5: X | E5: 1 | F5: 1
A6: 554 | B6: Rookie Impact Musah | C6: X | E6: 1
A7: 555 | B7: Cillessen | C7: X | E7: 2 | F7: 2
A8: 556 | B8: Jaume | C8: X
A9: 557 | B9: Correia | C9: X | E9: 1
A10: 558 | B10: Gabriel | D10: X
A11: 559 | B11: Guillamón | C11: X | E11: 3
A12: 560 | B12: Diakhaby | C12: X
A13: 561 | B13: Gayà | C13: X
A14: 562 | B14: Lato (12A)
A15: 563 | B15: Wass (12B) | C15: X | E15: 1
A16: 564 | B16: Racic | C16: X | E16: 1 | F16: 1
A17: 565 | B17: Cheryshev | C17: X
A18: 566 | B18: Carlos Soler | C18: X
A19: 567 | B19: Kang-In Lee (16A) | E19: 2 | F19: 1
A20: 568 | B20: Koba (16B) | C20: X | E20: 2
A21: 569 | B21: Guedes | C21: X
A22: 570 | B22: Musah | C22: X
A23: 571 | B23: Maxi Gómez | C23: X | E23: 1 | F23: 1
A24: 572 | B24: Álex Blanco (20A) | E24: 6 | F24: 1
A25: 573 | B25: Manu Vallejo (20B) | C25: X
A26: 574 | B26: Hélder Costa (14BIS)
A27: 575 | B27: Hugo Duro (18BIS)

Sheet VILLARREAL CF
A1: VILLARREAL CF
A2: Nº | B2: Jugador / Cromo | C2: Tengo | D2: Pedir | E2: Repetidos | F2: Enviados
A3: 581 | B3: Escudo Villarreal CF | C3: X | E3: 1
A4: 582 | B4: Entrenador - Unai Emery | C4: X
A5: 583 | B5: Gerard Moreno | C5: X | E5: 1
A6: 584 | B6: Rookie Impact Yeremi Pino | C6: X | E6: 1
A7: 585 | B7: Sergio Asenjo | D7: X
A8: 586 | B8: Rulli | C8: X | E8: 1
A9: 587 | B9: Mario
A10: 588 | B10: Albiol | C10: X
A11: 589 | B11: Pau Torres | D11: X
A12: 590 | B12: Foyth
A13: 591 | B13: Pedraza (11A) | E13: 1
A14: 592 | B14: Estupiñán (11B) | C14: X
A15: 593 | B15: Iborra | C15: X
A16: 594 | B16: Capoue | C16: X
A17: 595 | B17: Moi Gómez | D17: X
A18: 596 | B18: Coquelin | C18: X
A19: 597 | B19: Manu Trigueros | C19: X
A20: 598 | B20: Parejo | C20: X
A21: 599 | B21: Alcácer (18A) | E21: 1
A22: 600 | B22: Yeremi Pino (18B) | C22: X
A23: 601 | B23: Gerard Moreno | C23: X
A24: 602 | B24: Chukwueze (20A) | C24: X
A25: 603 | B25: Fer Niño (20B)
A26: 604 | B26: Rubén Peña (7BIS) | C26: X
A27: 605 | B27: Alberto Moreno (10BIS) | C27: X

Sheet LEYENDAS LaLiga
A1: LEYENDAS LaLiga
A2: Nº | B2: Jugador / Cromo | C2: Tengo | D2: Pedir | E2: Repetidos | F2: Enviados
A3: 611 | B3: ARKONADA – Real Sociedad | D3: X
A4: 612 | B4: BEBETO – Deportivo | C4: X
A5: 613 | B5: BECKHAM – Real Madrid | C5: X | E5: 2 | F5: 1
A6: 614 | B6: BUTRAGUEÑO – Real Madrid | C6: X | E6: 3
A7: 615 | B7: CASILLAS – Real Madrid | C7: X | E7: 1
A8: 616 | B8: CRISTIANO RONALDO – Real Madrid | D8: X
A9: 617 | B9: CRUYFF – Barcelona | C9: X | E9: 1 | F9: 1
A10: 618 | B10: DEL BOSQUE – Real Madrid | C10: X | E10: 1
A11: 619 | B11: FERNANDO SANZ - Málaga | C11: X | E11: 1 | F11: 1
A12: 620 | B12: FERNANDO TORRES – Atlético | C12: X | E12: 1
A13: 621 | B13: FUTRE – Atlético | C13: X
A14: 622 | B14: GORDILLO – Betis | C14: X
A15: 623 | B15: HUGO SÁNCHEZ – Real Madrid | C15: X | E15: 1 | F15: 1
A16: 624 | B16: INIESTA – Barcelona | C16: X | E16: 1
A17: 625 | B17: IRIBAR - Athletic | C17: X | E17: 4
A18: 626 | B18: KANOUTÉ - Sevilla | C18: X | E18: 1
A19: 627 | B19: KEMPES – Valencia | C19: X | E19: 4
A20: 628 | B20: KOEMAN – Barcelona | C20: X | E20: 1
A21: 629 | B21: MARADONA – Barcelona | C21: X | E21: 1 | F21: 1
A22: 630 | B22: MARCOS SENNA – Villarreal | D22: X
A23: 631 | B23: MOSTOVOI – Celta | C23: X
A24: 632 | B24: PANTIC – Atlético | C24: X
A25: 633 | B25: PUYOL – Barcelona | C25: X
A26: 634 | B26: QUINI - Sporting | C26: X | E26: 2
A27: 635 | B27: RAÚL – Real Madrid | C27: X | E27: 1
A28: 636 | B28: RONALDINHO – Barcelona | C28: X
A29: 637 | B29: SERGIO RAMOS – Real Madrid | C29: X | E29: 2
A30: 638 | B30: STOICHKOV – Barcelona | C30: X | E30: 1
A31: 639 | B31: TAMUDO – Espanyol | C31: X | E31: 3
A32: 640 | B32: VILLA – Valencia | C32: X | E32: 2
A33: 641 | B33: XAVI – Barcelona | C33: X | E33: 1
A34: 642 | B34: ZIDANE – Real Madrid | D34: X

Sheet FICHAJES DE INVIERNO
A1: FICHAJES DE INVIERNO
A2: Nº | B2: Jugador / Cromo | C2: Tengo | D2: Pedir | E2: Repetidos | F2: Enviados
A3: 651 | B3: AGÜERO – Barcelona | C3: X
A4: 652 | B4: SABALY – Betis | C4: X | E4: 1
A5: 653 | B5: KIKE GARCÍA – Osasuna | C5: X
A6: 654 | B6: ERIC GARCÍA – Barcelona | C6: X | E6: 1
A7: 655 | B7: HAROYAN – Cádiz | C7: X | E7: 1
A8: 656 | B8: MANU GARCÍA – Alavés | C8: X | E8: 1
A9: 657 | B9: MAFFEO – Mallorca | C9: X | E9: 2
A10: 658 | B10: MANDI – Villarreal | C10: X
A11: 659 | B11: SOLDADO – Levante | C11: X
A12: 660 | B12: ALARCÓN – Cádiz | C12: X
A13: 661 | B13: CERVI – Celta | C13: X
A14: 662 | B14: JAUME COSTA – Mallorca | C14: X
A15: 663 | B15: BOULAYE DIA – Villarreal | C15: X | E15: 1
A16: 664 | B16: VITOLO – Getafe | C16: X
A17: 665 | B17: BACCA – Granada | C17: X | E17: 1
A18: 666 | B18: ALDERETE – Valencia | C18: X
A19: 667 | B19: MARCOS PAULO – Atlético | C19: X | E19: 1
A20: 668 | B20: ALABA – Real Madrid | C20: X | E20: 1
A21: 669 | B21: MACÍAS – Getafe | C21: X | E21: 1
A22: 670 | B22: ÁNGEL – Mallorca | C22: X
A23: 671 | B23: ARZAMENDIA – Cádiz | C23: X
A24: 672 | B24: DEPAY – Barcelona | C24: X | E24: 1
A25: 673 | B25: PATHÉ CISS – Rayo | C25: X
A26: 674 | B26: SERGI GÓMEZ – Espanyol | C26: X
A27: 675 | B27: NTEKA – Rayo | C27: X | E27: 1
A28: 676 | B28: NICO WILLIAMS – Athletic | C28: X | E28: 3
A29: 677 | B29: LAMELA – Sevilla | C29: X
A30: 678 | B30: DE PAUL – Atlético | C30: X
A31: 679 | B31: LOUM - Alavés | C31: X
A32: 680 | B32: KUBO - Mallorca | C32: X
A33: 681 | B33: AUGUSTINSSON - Sevilla | D33: X
A34: 682 | B34: EMERSON - Barcelona | C34: X | E34: 1 | F34: 1
A35: 683 | B35: ROCO - Elche | C35: X
A36: 684 | B36: MORLANES - Espanyol | C36: X
A37: 685 | B37: MAMARDASHVILI - Valencia | C37: X
A38: 686 | B38: DIEGO RICO - Real Sociedad | C38: X
A39: 687 | B39: ANDONE - Cádiz | C39: X
A40: 688 | B40: FER NIÑO - Mallorca | C40: X
...

Sheet 50 ANIVERSARIO
A1: 50 ANIVERSARIO
A2: Nº | B2: Jugador / Cromo | C2: Tengo | D2: Pedir | E2: Repetidos | F2: Enviados
A3: 721 | B3: Logo conmemorativo 50 aniversario | C3: X | E3: 4
A4: 722 | B4: ZUBIZARRETA – Más partidos en LaLiga | C4: X | E4: 0
A5: 723 | B5: MESSI – Más goles en LaLiga | C5: X | E5: 3 | F5: 1
A6: 724 | B6: Ranking 50 años (1) | C6: X | E6: 2 | F6: 2
A7: 725 | B7: Ranking 50 años (2) | C7: X | E7: 2
A8: 726 | B8: Ranking 50 años (3) | C8: X | E8: 1
A9: 727 | B9: GENTO – Más Ligas ganadas | C9: X | E9: 1 | F9: 1
A10: 728 | B10: JOAQUÍN – Jugador en activo con más partidos en LaLiga | D10: X | E10: 0
A11: 729 | B11: MESSI – Más Balones de Oro en LaLiga | D11: X | E11: 0
