Workbook

Sheet RESUMEN
A1: ÁLBUM PANINI FIFA WORLD CUP 2026 — SEGUIMIENTO
A2: Sección | B2: Total | C2: Faltan | D2: Pedir | E2: Repetidos | F2: Enviados | G2: Disponibles
A3: INTRODUCCIÓN | B3: 9 | C3: =COUNTIF(INTRODUCCIÓN!C3:C11,"") -> 0 | D3: =COUNTIF(INTRODUCCIÓN!D3:D11,"X") -> 0 | E3: =SUMIF(INTRODUCCIÓN!E3:E11,">"&0,INTRODUCCIÓN!E3:E11) -> 8 | F3: =SUM(INTRODUCCIÓN!F3:F11) -> 8 | G3: =SUM(INTRODUCCIÓN!G3:G11) -> 0
A4: GRUPO A · México | B4: 20 | C4: =COUNTIF('GRUPO A · México'!C3:C22,"") -> 0 | D4: =COUNTIF('GRUPO A · México'!D3:D22,"X") -> 0 | E4: =SUMIF('GRUPO A · México'!E3:E22,">"&0,'GRUPO A · México'!E3:E22) -> 12 | F4: =SUM('GRUPO A · México'!F3:F22) -> 12 | G4: =SUM('GRUPO A · México'!G3:G22) -> 0
A5: GRUPO A · South Africa | B5: 20 | C5: =COUNTIF('GRUPO A · South Africa'!C3:C22,"") -> 0 | D5: =COUNTIF('GRUPO A · South Africa'!D3:D22,"X") -> 0 | E5: =SUMIF('GRUPO A · South Africa'!E3:E22,">"&0,'GRUPO A · South Africa'!E3:E22) -> 20 | F5: =SUM('GRUPO A · South Africa'!F3:F22) -> 20 | G5: =SUM('GRUPO A · South Africa'!G3:G22) -> 0
A6: GRUPO A · Korea Republic | B6: 20 | C6: =COUNTIF('GRUPO A · Korea Republic'!C3:C22,"") -> 0 | D6: =COUNTIF('GRUPO A · Korea Republic'!D3:D22,"X") -> 0 | E6: =SUMIF('GRUPO A · Korea Republic'!E3:E22,">"&0,'GRUPO A · Korea Republic'!E3:E22) -> 18 | F6: =SUM('GRUPO A · Korea Republic'!F3:F22) -> 18 | G6: =SUM('GRUPO A · Korea Republic'!G3:G22) -> 0
A7: GRUPO A · Czechia | B7: 20 | C7: =COUNTIF('GRUPO A · Czechia'!C3:C22,"") -> 0 | D7: =COUNTIF('GRUPO A · Czechia'!D3:D22,"X") -> 0 | E7: =SUMIF('GRUPO A · Czechia'!E3:E22,">"&0,'GRUPO A · Czechia'!E3:E22) -> 18 | F7: =SUM('GRUPO A · Czechia'!F3:F22) -> 18 | G7: =SUM('GRUPO A · Czechia'!G3:G22) -> 0
A8: GRUPO B · Canadá | B8: 20 | C8: =COUNTIF('GRUPO B · Canadá'!C3:C22,"") -> 0 | D8: =COUNTIF('GRUPO B · Canadá'!D3:D22,"X") -> 0 | E8: =SUMIF('GRUPO B · Canadá'!E3:E22,">"&0,'GRUPO B · Canadá'!E3:E22) -> 13 | F8: =SUM('GRUPO B · Canadá'!F3:F22) -> 13 | G8: =SUM('GRUPO B · Canadá'!G3:G22) -> 0
A9: GRUPO B · Bosnia-Herzegovina | B9: 20 | C9: =COUNTIF('GRUPO B · Bosnia-Herzegovina'!C3:C22,"") -> 0 | D9: =COUNTIF('GRUPO B · Bosnia-Herzegovina'!D3:D22,"X") -> 0 | E9: =SUMIF('GRUPO B · Bosnia-Herzegovina'!E3:E22,">"&0,'GRUPO B · Bosnia-Herzegovina'!E3:E22) -> 20 | F9: =SUM('GRUPO B · Bosnia-Herzegovina'!F3:F22) -> 20 | G9: =SUM('GRUPO B · Bosnia-Herzegovina'!G3:G22) -> 0
A10: GRUPO B · Qatar | B10: 20 | C10: =COUNTIF('GRUPO B · Qatar'!C3:C22,"") -> 0 | D10: =COUNTIF('GRUPO B · Qatar'!D3:D22,"X") -> 0 | E10: =SUMIF('GRUPO B · Qatar'!E3:E22,">"&0,'GRUPO B · Qatar'!E3:E22) -> 14 | F10: =SUM('GRUPO B · Qatar'!F3:F22) -> 14 | G10: =SUM('GRUPO B · Qatar'!G3:G22) -> 0
A11: GRUPO B · Switzerland | B11: 20 | C11: =COUNTIF('GRUPO B · Switzerland'!C3:C22,"") -> 0 | D11: =COUNTIF('GRUPO B · Switzerland'!D3:D22,"X") -> 0 | E11: =SUMIF('GRUPO B · Switzerland'!E3:E22,">"&0,'GRUPO B · Switzerland'!E3:E22) -> 14 | F11: =SUM('GRUPO B · Switzerland'!F3:F22) -> 14 | G11: =SUM('GRUPO B · Switzerland'!G3:G22) -> 0
A12: GRUPO C · Brazil | B12: 20 | C12: =COUNTIF('GRUPO C · Brazil'!C3:C22,"") -> 0 | D12: =COUNTIF('GRUPO C · Brazil'!D3:D22,"X") -> 0 | E12: =SUMIF('GRUPO C · Brazil'!E3:E22,">"&0,'GRUPO C · Brazil'!E3:E22) -> 17 | F12: =SUM('GRUPO C · Brazil'!F3:F22) -> 17 | G12: =SUM('GRUPO C · Brazil'!G3:G22) -> 0
A13: GRUPO C · Morocco | B13: 20 | C13: =COUNTIF('GRUPO C · Morocco'!C3:C22,"") -> 0 | D13: =COUNTIF('GRUPO C · Morocco'!D3:D22,"X") -> 0 | E13: =SUMIF('GRUPO C · Morocco'!E3:E22,">"&0,'GRUPO C · Morocco'!E3:E22) -> 12 | F13: =SUM('GRUPO C · Morocco'!F3:F22) -> 12 | G13: =SUM('GRUPO C · Morocco'!G3:G22) -> 0
A14: GRUPO C · Haiti | B14: 20 | C14: =COUNTIF('GRUPO C · Haiti'!C3:C22,"") -> 0 | D14: =COUNTIF('GRUPO C · Haiti'!D3:D22,"X") -> 0 | E14: =SUMIF('GRUPO C · Haiti'!E3:E22,">"&0,'GRUPO C · Haiti'!E3:E22) -> 15 | F14: =SUM('GRUPO C · Haiti'!F3:F22) -> 15 | G14: =SUM('GRUPO C · Haiti'!G3:G22) -> 0
A15: GRUPO C · Scotland | B15: 20 | C15: =COUNTIF('GRUPO C · Scotland'!C3:C22,"") -> 0 | D15: =COUNTIF('GRUPO C · Scotland'!D3:D22,"X") -> 0 | E15: =SUMIF('GRUPO C · Scotland'!E3:E22,">"&0,'GRUPO C · Scotland'!E3:E22) -> 20 | F15: =SUM('GRUPO C · Scotland'!F3:F22) -> 20 | G15: =SUM('GRUPO C · Scotland'!G3:G22) -> 0
A16: GRUPO D · USA | B16: 20 | C16: =COUNTIF('GRUPO D · USA'!C3:C22,"") -> 0 | D16: =COUNTIF('GRUPO D · USA'!D3:D22,"X") -> 0 | E16: =SUMIF('GRUPO D · USA'!E3:E22,">"&0,'GRUPO D · USA'!E3:E22) -> 14 | F16: =SUM('GRUPO D · USA'!F3:F22) -> 14 | G16: =SUM('GRUPO D · USA'!G3:G22) -> 0
A17: GRUPO D · Paraguay | B17: 20 | C17: =COUNTIF('GRUPO D · Paraguay'!C3:C22,"") -> 0 | D17: =COUNTIF('GRUPO D · Paraguay'!D3:D22,"X") -> 0 | E17: =SUMIF('GRUPO D · Paraguay'!E3:E22,">"&0,'GRUPO D · Paraguay'!E3:E22) -> 17 | F17: =SUM('GRUPO D · Paraguay'!F3:F22) -> 17 | G17: =SUM('GRUPO D · Paraguay'!G3:G22) -> 0
A18: GRUPO D · Australia | B18: 20 | C18: =COUNTIF('GRUPO D · Australia'!C3:C22,"") -> 0 | D18: =COUNTIF('GRUPO D · Australia'!D3:D22,"X") -> 0 | E18: =SUMIF('GRUPO D · Australia'!E3:E22,">"&0,'GRUPO D · Australia'!E3:E22) -> 16 | F18: =SUM('GRUPO D · Australia'!F3:F22) -> 16 | G18: =SUM('GRUPO D · Australia'!G3:G22) -> 0
A19: GRUPO D · Türkiye | B19: 20 | C19: =COUNTIF('GRUPO D · Türkiye'!C3:C22,"") -> 0 | D19: =COUNTIF('GRUPO D · Türkiye'!D3:D22,"X") -> 0 | E19: =SUMIF('GRUPO D · Türkiye'!E3:E22,">"&0,'GRUPO D · Türkiye'!E3:E22) -> 15 | F19: =SUM('GRUPO D · Türkiye'!F3:F22) -> 15 | G19: =SUM('GRUPO D · Türkiye'!G3:G22) -> 0
A20: GRUPO E · Germany | B20: 20 | C20: =COUNTIF('GRUPO E · Germany'!C3:C22,"") -> 0 | D20: =COUNTIF('GRUPO E · Germany'!D3:D22,"X") -> 0 | E20: =SUMIF('GRUPO E · Germany'!E3:E22,">"&0,'GRUPO E · Germany'!E3:E22) -> 18 | F20: =SUM('GRUPO E · Germany'!F3:F22) -> 18 | G20: =SUM('GRUPO E · Germany'!G3:G22) -> 0
A21: GRUPO E · Curaçao | B21: 20 | C21: =COUNTIF('GRUPO E · Curaçao'!C3:C22,"") -> 0 | D21: =COUNTIF('GRUPO E · Curaçao'!D3:D22,"X") -> 0 | E21: =SUMIF('GRUPO E · Curaçao'!E3:E22,">"&0,'GRUPO E · Curaçao'!E3:E22) -> 16 | F21: =SUM('GRUPO E · Curaçao'!F3:F22) -> 16 | G21: =SUM('GRUPO E · Curaçao'!G3:G22) -> 0
A22: GRUPO E · Cote dIvoire | B22: 20 | C22: =COUNTIF('GRUPO E · Cote dIvoire'!C3:C22,"") -> 0 | D22: =COUNTIF('GRUPO E · Cote dIvoire'!D3:D22,"X") -> 0 | E22: =SUMIF('GRUPO E · Cote dIvoire'!E3:E22,">"&0,'GRUPO E · Cote dIvoire'!E3:E22) -> 18 | F22: =SUM('GRUPO E · Cote dIvoire'!F3:F22) -> 18 | G22: =SUM('GRUPO E · Cote dIvoire'!G3:G22) -> 0
A23: GRUPO E · Ecuador | B23: 20 | C23: =COUNTIF('GRUPO E · Ecuador'!C3:C22,"") -> 0 | D23: =COUNTIF('GRUPO E · Ecuador'!D3:D22,"X") -> 0 | E23: =SUMIF('GRUPO E · Ecuador'!E3:E22,">"&0,'GRUPO E · Ecuador'!E3:E22) -> 20 | F23: =SUM('GRUPO E · Ecuador'!F3:F22) -> 20 | G23: =SUM('GRUPO E · Ecuador'!G3:G22) -> 0
A24: GRUPO F · Netherlands | B24: 20 | C24: =COUNTIF('GRUPO F · Netherlands'!C3:C22,"") -> 0 | D24: =COUNTIF('GRUPO F · Netherlands'!D3:D22,"X") -> 0 | E24: =SUMIF('GRUPO F · Netherlands'!E3:E22,">"&0,'GRUPO F · Netherlands'!E3:E22) -> 15 | F24: =SUM('GRUPO F · Netherlands'!F3:F22) -> 15 | G24: =SUM('GRUPO F · Netherlands'!G3:G22) -> 0
A25: GRUPO F · Japan | B25: 20 | C25: =COUNTIF('GRUPO F · Japan'!C3:C22,"") -> 0 | D25: =COUNTIF('GRUPO F · Japan'!D3:D22,"X") -> 0 | E25: =SUMIF('GRUPO F · Japan'!E3:E22,">"&0,'GRUPO F · Japan'!E3:E22) -> 15 | F25: =SUM('GRUPO F · Japan'!F3:F22) -> 15 | G25: =SUM('GRUPO F · Japan'!G3:G22) -> 0
A26: GRUPO F · Sweden | B26: 20 | C26: =COUNTIF('GRUPO F · Sweden'!C3:C22,"") -> 0 | D26: =COUNTIF('GRUPO F · Sweden'!D3:D22,"X") -> 0 | E26: =SUMIF('GRUPO F · Sweden'!E3:E22,">"&0,'GRUPO F · Sweden'!E3:E22) -> 14 | F26: =SUM('GRUPO F · Sweden'!F3:F22) -> 14 | G26: =SUM('GRUPO F · Sweden'!G3:G22) -> 0
A27: GRUPO F · Tunisia | B27: 20 | C27: =COUNTIF('GRUPO F · Tunisia'!C3:C22,"") -> 0 | D27: =COUNTIF('GRUPO F · Tunisia'!D3:D22,"X") -> 0 | E27: =SUMIF('GRUPO F · Tunisia'!E3:E22,">"&0,'GRUPO F · Tunisia'!E3:E22) -> 9 | F27: =SUM('GRUPO F · Tunisia'!F3:F22) -> 9 | G27: =SUM('GRUPO F · Tunisia'!G3:G22) -> 0
A28: GRUPO G · Belgium | B28: 20 | C28: =COUNTIF('GRUPO G · Belgium'!C3:C22,"") -> 0 | D28: =COUNTIF('GRUPO G · Belgium'!D3:D22,"X") -> 0 | E28: =SUMIF('GRUPO G · Belgium'!E3:E22,">"&0,'GRUPO G · Belgium'!E3:E22) -> 18 | F28: =SUM('GRUPO G · Belgium'!F3:F22) -> 18 | G28: =SUM('GRUPO G · Belgium'!G3:G22) -> 0
A29: GRUPO G · Egypt | B29: 20 | C29: =COUNTIF('GRUPO G · Egypt'!C3:C22,"") -> 0 | D29: =COUNTIF('GRUPO G · Egypt'!D3:D22,"X") -> 0 | E29: =SUMIF('GRUPO G · Egypt'!E3:E22,">"&0,'GRUPO G · Egypt'!E3:E22) -> 12 | F29: =SUM('GRUPO G · Egypt'!F3:F22) -> 12 | G29: =SUM('GRUPO G · Egypt'!G3:G22) -> 0
A30: GRUPO G · IR Iran | B30: 20 | C30: =COUNTIF('GRUPO G · IR Iran'!C3:C22,"") -> 0 | D30: =COUNTIF('GRUPO G · IR Iran'!D3:D22,"X") -> 0 | E30: =SUMIF('GRUPO G · IR Iran'!E3:E22,">"&0,'GRUPO G · IR Iran'!E3:E22) -> 18 | F30: =SUM('GRUPO G · IR Iran'!F3:F22) -> 18 | G30: =SUM('GRUPO G · IR Iran'!G3:G22) -> 0
A31: GRUPO G · New Zealand | B31: 20 | C31: =COUNTIF('GRUPO G · New Zealand'!C3:C22,"") -> 0 | D31: =COUNTIF('GRUPO G · New Zealand'!D3:D22,"X") -> 0 | E31: =SUMIF('GRUPO G · New Zealand'!E3:E22,">"&0,'GRUPO G · New Zealand'!E3:E22) -> 14 | F31: =SUM('GRUPO G · New Zealand'!F3:F22) -> 14 | G31: =SUM('GRUPO G · New Zealand'!G3:G22) -> 0
A32: GRUPO H · España | B32: 20 | C32: =COUNTIF('GRUPO H · España'!C3:C22,"") -> 0 | D32: =COUNTIF('GRUPO H · España'!D3:D22,"X") -> 0 | E32: =SUMIF('GRUPO H · España'!E3:E22,">"&0,'GRUPO H · España'!E3:E22) -> 12 | F32: =SUM('GRUPO H · España'!F3:F22) -> 12 | G32: =SUM('GRUPO H · España'!G3:G22) -> 0
A33: GRUPO H · Cabo Verde | B33: 20 | C33: =COUNTIF('GRUPO H · Cabo Verde'!C3:C22,"") -> 0 | D33: =COUNTIF('GRUPO H · Cabo Verde'!D3:D22,"X") -> 0 | E33: =SUMIF('GRUPO H · Cabo Verde'!E3:E22,">"&0,'GRUPO H · Cabo Verde'!E3:E22) -> 20 | F33: =SUM('GRUPO H · Cabo Verde'!F3:F22) -> 20 | G33: =SUM('GRUPO H · Cabo Verde'!G3:G22) -> 0
A34: GRUPO H · Saudi Arabia | B34: 20 | C34: =COUNTIF('GRUPO H · Saudi Arabia'!C3:C22,"") -> 0 | D34: =COUNTIF('GRUPO H · Saudi Arabia'!D3:D22,"X") -> 0 | E34: =SUMIF('GRUPO H · Saudi Arabia'!E3:E22,">"&0,'GRUPO H · Saudi Arabia'!E3:E22) -> 16 | F34: =SUM('GRUPO H · Saudi Arabia'!F3:F22) -> 16 | G34: =SUM('GRUPO H · Saudi Arabia'!G3:G22) -> 0
A35: GRUPO H · Uruguay | B35: 20 | C35: =COUNTIF('GRUPO H · Uruguay'!C3:C22,"") -> 0 | D35: =COUNTIF('GRUPO H · Uruguay'!D3:D22,"X") -> 0 | E35: =SUMIF('GRUPO H · Uruguay'!E3:E22,">"&0,'GRUPO H · Uruguay'!E3:E22) -> 15 | F35: =SUM('GRUPO H · Uruguay'!F3:F22) -> 15 | G35: =SUM('GRUPO H · Uruguay'!G3:G22) -> 0
A36: GRUPO I · France | B36: 20 | C36: =COUNTIF('GRUPO I · France'!C3:C22,"") -> 0 | D36: =COUNTIF('GRUPO I · France'!D3:D22,"X") -> 0 | E36: =SUMIF('GRUPO I · France'!E3:E22,">"&0,'GRUPO I · France'!E3:E22) -> 7 | F36: =SUM('GRUPO I · France'!F3:F22) -> 7 | G36: =SUM('GRUPO I · France'!G3:G22) -> 0
A37: GRUPO I · Senegal | B37: 20 | C37: =COUNTIF('GRUPO I · Senegal'!C3:C22,"") -> 0 | D37: =COUNTIF('GRUPO I · Senegal'!D3:D22,"X") -> 0 | E37: =SUMIF('GRUPO I · Senegal'!E3:E22,">"&0,'GRUPO I · Senegal'!E3:E22) -> 11 | F37: =SUM('GRUPO I · Senegal'!F3:F22) -> 11 | G37: =SUM('GRUPO I · Senegal'!G3:G22) -> 0
A38: GRUPO I · Iraq | B38: 20 | C38: =COUNTIF('GRUPO I · Iraq'!C3:C22,"") -> 0 | D38: =COUNTIF('GRUPO I · Iraq'!D3:D22,"X") -> 0 | E38: =SUMIF('GRUPO I · Iraq'!E3:E22,">"&0,'GRUPO I · Iraq'!E3:E22) -> 19 | F38: =SUM('GRUPO I · Iraq'!F3:F22) -> 19 | G38: =SUM('GRUPO I · Iraq'!G3:G22) -> 0
A39: GRUPO I · Norway | B39: 20 | C39: =COUNTIF('GRUPO I · Norway'!C3:C22,"") -> 0 | D39: =COUNTIF('GRUPO I · Norway'!D3:D22,"X") -> 0 | E39: =SUMIF('GRUPO I · Norway'!E3:E22,">"&0,'GRUPO I · Norway'!E3:E22) -> 12 | F39: =SUM('GRUPO I · Norway'!F3:F22) -> 12 | G39: =SUM('GRUPO I · Norway'!G3:G22) -> 0
A40: GRUPO J · Argentina | B40: 20 | C40: =COUNTIF('GRUPO J · Argentina'!C3:C22,"") -> 0 | D40: =COUNTIF('GRUPO J · Argentina'!D3:D22,"X") -> 0 | E40: =SUMIF('GRUPO J · Argentina'!E3:E22,">"&0,'GRUPO J · Argentina'!E3:E22) -> 19 | F40: =SUM('GRUPO J · Argentina'!F3:F22) -> 19 | G40: =SUM('GRUPO J · Argentina'!G3:G22) -> 0
...

Sheet INTRODUCCIÓN
A1: INTRODUCCIÓN
A2: Código | B2: Jugador / Cromo | C2: Tengo | D2: Pedir | E2: Repetidos | F2: Enviados | G2: Disponibles
A3: 00 | B3: Logo Panini | C3: X | G3: =MAX(0,IF(E3="",0,E3)-IF(F3="",0,F3)) -> 0
A4: FWC1 | B4: Logo Mundial - Parte Superior | C4: X | G4: =MAX(0,IF(E4="",0,E4)-IF(F4="",0,F4)) -> 0
A5: FWC2 | B5: Logo Mundial - Parte Inferior | C5: X | E5: 1 | F5: 1 | G5: =MAX(0,IF(E5="",0,E5)-IF(F5="",0,F5)) -> 0
A6: FWC3 | B6: Official Mascots | C6: X | G6: =MAX(0,IF(E6="",0,E6)-IF(F6="",0,F6)) -> 0
A7: FWC4 | B7: Official Slogan | C7: X | E7: 1 | F7: 1 | G7: =MAX(0,IF(E7="",0,E7)-IF(F7="",0,F7)) -> 0
A8: FWC5 | B8: Official Ball | C8: X | E8: 1 | F8: 1 | G8: =MAX(0,IF(E8="",0,E8)-IF(F8="",0,F8)) -> 0
A9: FWC6 | B9: Canadá - Host Country Emblem | C9: X | E9: 1 | F9: 1 | G9: =MAX(0,IF(E9="",0,E9)-IF(F9="",0,F9)) -> 0
A10: FWC7 | B10: México - Host Country Emblem | C10: X | E10: 1 | F10: 1 | G10: =MAX(0,IF(E10="",0,E10)-IF(F10="",0,F10)) -> 0
A11: FWC8 | B11: USA - Host Country Emblem | C11: X | E11: 3 | F11: 3 | G11: =MAX(0,IF(E11="",0,E11)-IF(F11="",0,F11)) -> 0

Sheet GRUPO A · México
A1: GRUPO A · México
A2: Código | B2: Jugador / Cromo | C2: Tengo | D2: Pedir | E2: Repetidos | F2: Enviados | G2: Disponibles
A3: MEX1 | B3: Escudo | C3: X | G3: =MAX(0,IF(E3="",0,E3)-IF(F3="",0,F3)) -> 0
A4: MEX2 | B4: Luis Malagón | C4: X | G4: =MAX(0,IF(E4="",0,E4)-IF(F4="",0,F4)) -> 0
A5: MEX3 | B5: Johan Vásquez | C5: X | G5: =MAX(0,IF(E5="",0,E5)-IF(F5="",0,F5)) -> 0
A6: MEX4 | B6: Jorge Sánchez | C6: X | G6: =MAX(0,IF(E6="",0,E6)-IF(F6="",0,F6)) -> 0
A7: MEX5 | B7: César Montes | C7: X | G7: =MAX(0,IF(E7="",0,E7)-IF(F7="",0,F7)) -> 0
A8: MEX6 | B8: Jesús Gallardo | C8: X | E8: 2 | F8: 2 | G8: =MAX(0,IF(E8="",0,E8)-IF(F8="",0,F8)) -> 0
A9: MEX7 | B9: Israel Reyes | C9: X | G9: =MAX(0,IF(E9="",0,E9)-IF(F9="",0,F9)) -> 0
A10: MEX8 | B10: Diego Lainez | C10: X | E10: 3 | F10: 3 | G10: =MAX(0,IF(E10="",0,E10)-IF(F10="",0,F10)) -> 0
A11: MEX9 | B11: Carlos Rodríguez | C11: X | G11: =MAX(0,IF(E11="",0,E11)-IF(F11="",0,F11)) -> 0
A12: MEX10 | B12: Edson Álvarez | C12: X | G12: =MAX(0,IF(E12="",0,E12)-IF(F12="",0,F12)) -> 0
A13: MEX11 | B13: Orbelin Pineda | C13: X | E13: 3 | F13: 3 | G13: =MAX(0,IF(E13="",0,E13)-IF(F13="",0,F13)) -> 0
A14: MEX12 | B14: Marcel Ruiz | C14: X | E14: 1 | F14: 1 | G14: =MAX(0,IF(E14="",0,E14)-IF(F14="",0,F14)) -> 0
A15: MEX13 | B15: Foto Equipo | C15: X | G15: =MAX(0,IF(E15="",0,E15)-IF(F15="",0,F15)) -> 0
A16: MEX14 | B16: Érick Sánchez | C16: X | G16: =MAX(0,IF(E16="",0,E16)-IF(F16="",0,F16)) -> 0
A17: MEX15 | B17: Hirving Lozano | C17: X | G17: =MAX(0,IF(E17="",0,E17)-IF(F17="",0,F17)) -> 0
A18: MEX16 | B18: Santiago Giménez | C18: X | E18: 1 | F18: 1 | G18: =MAX(0,IF(E18="",0,E18)-IF(F18="",0,F18)) -> 0
A19: MEX17 | B19: Raúl Jiménez | C19: X | G19: =MAX(0,IF(E19="",0,E19)-IF(F19="",0,F19)) -> 0
A20: MEX18 | B20: Alexis Vega | C20: X | E20: 2 | F20: 2 | G20: =MAX(0,IF(E20="",0,E20)-IF(F20="",0,F20)) -> 0
A21: MEX19 | B21: Roberto Alvarado | C21: X | G21: =MAX(0,IF(E21="",0,E21)-IF(F21="",0,F21)) -> 0
A22: MEX20 | B22: César Huerta | C22: X | G22: =MAX(0,IF(E22="",0,E22)-IF(F22="",0,F22)) -> 0

Sheet GRUPO A · South Africa
A1: GRUPO A · South Africa
A2: Código | B2: Jugador / Cromo | C2: Tengo | D2: Pedir | E2: Repetidos | F2: Enviados | G2: Disponibles
A3: RSA1 | B3: Escudo | C3: X | E3: 2 | F3: 2 | G3: =MAX(0,IF(E3="",0,E3)-IF(F3="",0,F3)) -> 0
A4: RSA2 | B4: Ronwen Williams | C4: X | G4: =MAX(0,IF(E4="",0,E4)-IF(F4="",0,F4)) -> 0
A5: RSA3 | B5: Sipho Chaine | C5: X | G5: =MAX(0,IF(E5="",0,E5)-IF(F5="",0,F5)) -> 0
A6: RSA4 | B6: Aubrey Modiba | C6: X | G6: =MAX(0,IF(E6="",0,E6)-IF(F6="",0,F6)) -> 0
A7: RSA5 | B7: Samukele Kabini | C7: X | G7: =MAX(0,IF(E7="",0,E7)-IF(F7="",0,F7)) -> 0
A8: RSA6 | B8: Mbekezeli Mbokazi | C8: X | E8: 3 | F8: 3 | G8: =MAX(0,IF(E8="",0,E8)-IF(F8="",0,F8)) -> 0
A9: RSA7 | B9: Khulumani Ndamane | C9: X | G9: =MAX(0,IF(E9="",0,E9)-IF(F9="",0,F9)) -> 0
A10: RSA8 | B10: Siyabonga Ngezana | C10: X | E10: 2 | F10: 2 | G10: =MAX(0,IF(E10="",0,E10)-IF(F10="",0,F10)) -> 0
A11: RSA9 | B11: Khuliso Mudau | C11: X | E11: 1 | F11: 1 | G11: =MAX(0,IF(E11="",0,E11)-IF(F11="",0,F11)) -> 0
A12: RSA10 | B12: Nkosinathi Sibisi | C12: X | E12: 1 | F12: 1 | G12: =MAX(0,IF(E12="",0,E12)-IF(F12="",0,F12)) -> 0
A13: RSA11 | B13: Teboho Mokoena | C13: X | G13: =MAX(0,IF(E13="",0,E13)-IF(F13="",0,F13)) -> 0
A14: RSA12 | B14: Thalente Mbatha | C14: X | E14: 1 | F14: 1 | G14: =MAX(0,IF(E14="",0,E14)-IF(F14="",0,F14)) -> 0
A15: RSA13 | B15: Foto Equipo | C15: X | E15: 2 | F15: 2 | G15: =MAX(0,IF(E15="",0,E15)-IF(F15="",0,F15)) -> 0
A16: RSA14 | B16: Bathusi Aubaas | C16: X | E16: 1 | F16: 1 | G16: =MAX(0,IF(E16="",0,E16)-IF(F16="",0,F16)) -> 0
A17: RSA15 | B17: Yaya Sithole | C17: X | G17: =MAX(0,IF(E17="",0,E17)-IF(F17="",0,F17)) -> 0
A18: RSA16 | B18: Sipho Mbule | C18: X | E18: 2 | F18: 2 | G18: =MAX(0,IF(E18="",0,E18)-IF(F18="",0,F18)) -> 0
A19: RSA17 | B19: Lyle Foster | C19: X | E19: 3 | F19: 3 | G19: =MAX(0,IF(E19="",0,E19)-IF(F19="",0,F19)) -> 0
A20: RSA18 | B20: Iqraam Rayners | C20: X | G20: =MAX(0,IF(E20="",0,E20)-IF(F20="",0,F20)) -> 0
A21: RSA19 | B21: Mohau Nkota | C21: X | E21: 1 | F21: 1 | G21: =MAX(0,IF(E21="",0,E21)-IF(F21="",0,F21)) -> 0
A22: RSA20 | B22: Oswin Appollis | C22: X | E22: 1 | F22: 1 | G22: =MAX(0,IF(E22="",0,E22)-IF(F22="",0,F22)) -> 0

Sheet GRUPO A · Korea Republic
A1: GRUPO A · Korea Republic
A2: Código | B2: Jugador / Cromo | C2: Tengo | D2: Pedir | E2: Repetidos | F2: Enviados | G2: Disponibles
A3: KOR1 | B3: Escudo | C3: X | G3: =MAX(0,IF(E3="",0,E3)-IF(F3="",0,F3)) -> 0
A4: KOR2 | B4: Hyeonwoo Jo | C4: X | G4: =MAX(0,IF(E4="",0,E4)-IF(F4="",0,F4)) -> 0
A5: KOR3 | B5: Seunggyu Kim | C5: X | E5: 1 | F5: 1 | G5: =MAX(0,IF(E5="",0,E5)-IF(F5="",0,F5)) -> 0
A6: KOR4 | B6: Minjae Kim | C6: X | E6: 1 | F6: 1 | G6: =MAX(0,IF(E6="",0,E6)-IF(F6="",0,F6)) -> 0
A7: KOR5 | B7: Yumin Cho | C7: X | E7: 3 | F7: 3 | G7: =MAX(0,IF(E7="",0,E7)-IF(F7="",0,F7)) -> 0
A8: KOR6 | B8: Youngwoo Seol | C8: X | E8: 2 | F8: 2 | G8: =MAX(0,IF(E8="",0,E8)-IF(F8="",0,F8)) -> 0
A9: KOR7 | B9: Hanbeom Lee | C9: X | E9: 1 | F9: 1 | G9: =MAX(0,IF(E9="",0,E9)-IF(F9="",0,F9)) -> 0
A10: KOR8 | B10: Taeseok Lee | C10: X | G10: =MAX(0,IF(E10="",0,E10)-IF(F10="",0,F10)) -> 0
A11: KOR9 | B11: Myungjae Lee | C11: X | E11: 2 | F11: 2 | G11: =MAX(0,IF(E11="",0,E11)-IF(F11="",0,F11)) -> 0
A12: KOR10 | B12: Jaesung Lee | C12: X | G12: =MAX(0,IF(E12="",0,E12)-IF(F12="",0,F12)) -> 0
A13: KOR11 | B13: Inbeom Hwang | C13: X | G13: =MAX(0,IF(E13="",0,E13)-IF(F13="",0,F13)) -> 0
A14: KOR12 | B14: Kangin Lee | C14: X | E14: 1 | F14: 1 | G14: =MAX(0,IF(E14="",0,E14)-IF(F14="",0,F14)) -> 0
A15: KOR13 | B15: Foto Equipo | C15: X | G15: =MAX(0,IF(E15="",0,E15)-IF(F15="",0,F15)) -> 0
A16: KOR14 | B16: Seungho Paik | C16: X | E16: 1 | F16: 1 | G16: =MAX(0,IF(E16="",0,E16)-IF(F16="",0,F16)) -> 0
A17: KOR15 | B17: Jens Castrop | C17: X | G17: =MAX(0,IF(E17="",0,E17)-IF(F17="",0,F17)) -> 0
A18: KOR16 | B18: Donggyeong Lee | C18: X | G18: =MAX(0,IF(E18="",0,E18)-IF(F18="",0,F18)) -> 0
A19: KOR17 | B19: Guesung Cho | C19: X | E19: 1 | F19: 1 | G19: =MAX(0,IF(E19="",0,E19)-IF(F19="",0,F19)) -> 0
A20: KOR18 | B20: Heungmin Son | C20: X | E20: 2 | F20: 2 | G20: =MAX(0,IF(E20="",0,E20)-IF(F20="",0,F20)) -> 0
A21: KOR19 | B21: Heechan Hwang | C21: X | E21: 3 | F21: 3 | G21: =MAX(0,IF(E21="",0,E21)-IF(F21="",0,F21)) -> 0
A22: KOR20 | B22: Hyeongyu Oh | C22: X | G22: =MAX(0,IF(E22="",0,E22)-IF(F22="",0,F22)) -> 0

Sheet GRUPO A · Czechia
A1: GRUPO A · Czechia
A2: Código | B2: Jugador / Cromo | C2: Tengo | D2: Pedir | E2: Repetidos | F2: Enviados | G2: Disponibles
A3: CZE1 | B3: Escudo | C3: X | E3: 1 | F3: 1 | G3: =MAX(0,IF(E3="",0,E3)-IF(F3="",0,F3)) -> 0
A4: CZE2 | B4: Matěj Kovář | C4: X | G4: =MAX(0,IF(E4="",0,E4)-IF(F4="",0,F4)) -> 0
A5: CZE3 | B5: Jindřich Staněk | C5: X | G5: =MAX(0,IF(E5="",0,E5)-IF(F5="",0,F5)) -> 0
A6: CZE4 | B6: Ladislav Krejčí | C6: X | E6: 1 | F6: 1 | G6: =MAX(0,IF(E6="",0,E6)-IF(F6="",0,F6)) -> 0
A7: CZE5 | B7: Vladimír Coufal | C7: X | G7: =MAX(0,IF(E7="",0,E7)-IF(F7="",0,F7)) -> 0
A8: CZE6 | B8: Jaroslav Zelený | C8: X | E8: 2 | F8: 2 | G8: =MAX(0,IF(E8="",0,E8)-IF(F8="",0,F8)) -> 0
A9: CZE7 | B9: Tomáš Holeš | C9: X | E9: 1 | F9: 1 | G9: =MAX(0,IF(E9="",0,E9)-IF(F9="",0,F9)) -> 0
A10: CZE8 | B10: David Zima | C10: X | E10: 1 | F10: 1 | G10: =MAX(0,IF(E10="",0,E10)-IF(F10="",0,F10)) -> 0
A11: CZE9 | B11: Michal Sadílek | C11: X | E11: 3 | F11: 3 | G11: =MAX(0,IF(E11="",0,E11)-IF(F11="",0,F11)) -> 0
A12: CZE10 | B12: Lukáš Provod | C12: X | E12: 1 | F12: 1 | G12: =MAX(0,IF(E12="",0,E12)-IF(F12="",0,F12)) -> 0
A13: CZE11 | B13: Lukáš Červ | C13: X | G13: =MAX(0,IF(E13="",0,E13)-IF(F13="",0,F13)) -> 0
A14: CZE12 | B14: Tomáš Souček | C14: X | E14: 4 | F14: 4 | G14: =MAX(0,IF(E14="",0,E14)-IF(F14="",0,F14)) -> 0
A15: CZE13 | B15: Foto Equipo | C15: X | G15: =MAX(0,IF(E15="",0,E15)-IF(F15="",0,F15)) -> 0
A16: CZE14 | B16: Pavel Šulc | C16: X | E16: 1 | F16: 1 | G16: =MAX(0,IF(E16="",0,E16)-IF(F16="",0,F16)) -> 0
A17: CZE15 | B17: Matěj Vydra | C17: X | G17: =MAX(0,IF(E17="",0,E17)-IF(F17="",0,F17)) -> 0
A18: CZE16 | B18: Vasil Kušej | C18: X | G18: =MAX(0,IF(E18="",0,E18)-IF(F18="",0,F18)) -> 0
A19: CZE17 | B19: Tomáš Chorý | C19: X | G19: =MAX(0,IF(E19="",0,E19)-IF(F19="",0,F19)) -> 0
A20: CZE18 | B20: Václav Černý | C20: X | E20: 1 | F20: 1 | G20: =MAX(0,IF(E20="",0,E20)-IF(F20="",0,F20)) -> 0
A21: CZE19 | B21: Adam Hložek | C21: X | G21: =MAX(0,IF(E21="",0,E21)-IF(F21="",0,F21)) -> 0
A22: CZE20 | B22: Patrik Schick | C22: X | E22: 2 | F22: 2 | G22: =MAX(0,IF(E22="",0,E22)-IF(F22="",0,F22)) -> 0

Sheet GRUPO B · Canadá
A1: GRUPO B · Canadá
A2: Código | B2: Jugador / Cromo | C2: Tengo | D2: Pedir | E2: Repetidos | F2: Enviados | G2: Disponibles
A3: CAN1 | B3: Escudo | C3: X | G3: =MAX(0,IF(E3="",0,E3)-IF(F3="",0,F3)) -> 0
A4: CAN2 | B4: Dayne St. Clair | C4: X | E4: 1 | F4: 1 | G4: =MAX(0,IF(E4="",0,E4)-IF(F4="",0,F4)) -> 0
A5: CAN3 | B5: Alphonso Davies | C5: X | E5: 1 | F5: 1 | G5: =MAX(0,IF(E5="",0,E5)-IF(F5="",0,F5)) -> 0
A6: CAN4 | B6: Alistair Johnston | C6: X | E6: 3 | F6: 3 | G6: =MAX(0,IF(E6="",0,E6)-IF(F6="",0,F6)) -> 0
A7: CAN5 | B7: Samuel Adekugbe | C7: X | G7: =MAX(0,IF(E7="",0,E7)-IF(F7="",0,F7)) -> 0
A8: CAN6 | B8: Samuel Richie Larvea | C8: X | E8: 1 | F8: 1 | G8: =MAX(0,IF(E8="",0,E8)-IF(F8="",0,F8)) -> 0
A9: CAN7 | B9: Derek Cornelius | C9: X | G9: =MAX(0,IF(E9="",0,E9)-IF(F9="",0,F9)) -> 0
A10: CAN8 | B10: Moïse Bombito | C10: X | G10: =MAX(0,IF(E10="",0,E10)-IF(F10="",0,F10)) -> 0
A11: CAN9 | B11: Kamal Miller | C11: X | E11: 1 | F11: 1 | G11: =MAX(0,IF(E11="",0,E11)-IF(F11="",0,F11)) -> 0
A12: CAN10 | B12: Stephen Eustáquio | C12: X | G12: =MAX(0,IF(E12="",0,E12)-IF(F12="",0,F12)) -> 0
A13: CAN11 | B13: Ismaël Koné | C13: X | E13: 3 | F13: 3 | G13: =MAX(0,IF(E13="",0,E13)-IF(F13="",0,F13)) -> 0
A14: CAN12 | B14: Jonathan Osorio | C14: X | G14: =MAX(0,IF(E14="",0,E14)-IF(F14="",0,F14)) -> 0
A15: CAN13 | B15: Foto Equipo | C15: X | G15: =MAX(0,IF(E15="",0,E15)-IF(F15="",0,F15)) -> 0
A16: CAN14 | B16: Jacob Shaffelburg | C16: X | G16: =MAX(0,IF(E16="",0,E16)-IF(F16="",0,F16)) -> 0
A17: CAN15 | B17: Mathieu Choinière | C17: X | E17: 1 | F17: 1 | G17: =MAX(0,IF(E17="",0,E17)-IF(F17="",0,F17)) -> 0
A18: CAN16 | B18: Niko Sigur | C18: X | G18: =MAX(0,IF(E18="",0,E18)-IF(F18="",0,F18)) -> 0
A19: CAN17 | B19: Tajon Buchanan | C19: X | E19: 2 | F19: 2 | G19: =MAX(0,IF(E19="",0,E19)-IF(F19="",0,F19)) -> 0
A20: CAN18 | B20: Liam Millar | C20: X | G20: =MAX(0,IF(E20="",0,E20)-IF(F20="",0,F20)) -> 0
A21: CAN19 | B21: Cyle Larin | C21: X | G21: =MAX(0,IF(E21="",0,E21)-IF(F21="",0,F21)) -> 0
A22: CAN20 | B22: Jonathan David | C22: X | G22: =MAX(0,IF(E22="",0,E22)-IF(F22="",0,F22)) -> 0

Sheet GRUPO B · Bosnia-Herzegovina
A1: GRUPO B · Bosnia-Herzegovina
A2: Código | B2: Jugador / Cromo | C2: Tengo | D2: Pedir | E2: Repetidos | F2: Enviados | G2: Disponibles
A3: BIH1 | B3: Escudo | C3: X | G3: =MAX(0,IF(E3="",0,E3)-IF(F3="",0,F3)) -> 0
A4: BIH2 | B4: Nikola Vasilj | C4: X | E4: 2 | F4: 2 | G4: =MAX(0,IF(E4="",0,E4)-IF(F4="",0,F4)) -> 0
A5: BIH3 | B5: Amar Dedić | C5: X | G5: =MAX(0,IF(E5="",0,E5)-IF(F5="",0,F5)) -> 0
A6: BIH4 | B6: Sead Kolašinac | C6: X | E6: 1 | F6: 1 | G6: =MAX(0,IF(E6="",0,E6)-IF(F6="",0,F6)) -> 0
A7: BIH5 | B7: Tarik Muharemović | C7: X | G7: =MAX(0,IF(E7="",0,E7)-IF(F7="",0,F7)) -> 0
A8: BIH6 | B8: Nihad Mujakić | C8: X | E8: 1 | F8: 1 | G8: =MAX(0,IF(E8="",0,E8)-IF(F8="",0,F8)) -> 0
A9: BIH7 | B9: Nikola Katić | C9: X | G9: =MAX(0,IF(E9="",0,E9)-IF(F9="",0,F9)) -> 0
A10: BIH8 | B10: Amir Hadžiahmetović | C10: X | G10: =MAX(0,IF(E10="",0,E10)-IF(F10="",0,F10)) -> 0
A11: BIH9 | B11: Benjamin Tahirović | C11: X | E11: 1 | F11: 1 | G11: =MAX(0,IF(E11="",0,E11)-IF(F11="",0,F11)) -> 0
A12: BIH10 | B12: Armin Gigović | C12: X | E12: 3 | F12: 3 | G12: =MAX(0,IF(E12="",0,E12)-IF(F12="",0,F12)) -> 0
A13: BIH11 | B13: Ivan Šunjić | C13: X | E13: 1 | F13: 1 | G13: =MAX(0,IF(E13="",0,E13)-IF(F13="",0,F13)) -> 0
A14: BIH12 | B14: Ivan Bašić | C14: X | G14: =MAX(0,IF(E14="",0,E14)-IF(F14="",0,F14)) -> 0
A15: BIH13 | B15: Foto Equipo | C15: X | E15: 4 | F15: 4 | G15: =MAX(0,IF(E15="",0,E15)-IF(F15="",0,F15)) -> 0
A16: BIH14 | B16: Dženis Burnić | C16: X | G16: =MAX(0,IF(E16="",0,E16)-IF(F16="",0,F16)) -> 0
A17: BIH15 | B17: Esmir Bajraktarevic | C17: X | E17: 1 | F17: 1 | G17: =MAX(0,IF(E17="",0,E17)-IF(F17="",0,F17)) -> 0
A18: BIH16 | B18: Amar Memić | C18: X | E18: 2 | F18: 2 | G18: =MAX(0,IF(E18="",0,E18)-IF(F18="",0,F18)) -> 0
A19: BIH17 | B19: Ermedin Demirović | C19: X | E19: 1 | F19: 1 | G19: =MAX(0,IF(E19="",0,E19)-IF(F19="",0,F19)) -> 0
A20: BIH18 | B20: Edin Džeko | C20: X | E20: 3 | F20: 3 | G20: =MAX(0,IF(E20="",0,E20)-IF(F20="",0,F20)) -> 0
A21: BIH19 | B21: Samed Baždar | C21: X | G21: =MAX(0,IF(E21="",0,E21)-IF(F21="",0,F21)) -> 0
A22: BIH20 | B22: Haris Tabaković | C22: X | G22: =MAX(0,IF(E22="",0,E22)-IF(F22="",0,F22)) -> 0

Sheet GRUPO B · Qatar
A1: GRUPO B · Qatar
A2: Código | B2: Jugador / Cromo | C2: Tengo | D2: Pedir | E2: Repetidos | F2: Enviados | G2: Disponibles
A3: QAT1 | B3: Escudo | C3: X | E3: 1 | F3: 1 | G3: =MAX(0,IF(E3="",0,E3)-IF(F3="",0,F3)) -> 0
A4: QAT2 | B4: Meshaal Barsham | C4: X | E4: 1 | F4: 1 | G4: =MAX(0,IF(E4="",0,E4)-IF(F4="",0,F4)) -> 0
A5: QAT3 | B5: Sultan Albrake | C5: X | G5: =MAX(0,IF(E5="",0,E5)-IF(F5="",0,F5)) -> 0
A6: QAT4 | B6: Lucas Mendes | C6: X | E6: 3 | F6: 3 | G6: =MAX(0,IF(E6="",0,E6)-IF(F6="",0,F6)) -> 0
A7: QAT5 | B7: Homam Ahmed | C7: X | E7: 1 | F7: 1 | G7: =MAX(0,IF(E7="",0,E7)-IF(F7="",0,F7)) -> 0
A8: QAT6 | B8: Boualem Khoukhi | C8: X | G8: =MAX(0,IF(E8="",0,E8)-IF(F8="",0,F8)) -> 0
A9: QAT7 | B9: Pedro Miguel | C9: X | G9: =MAX(0,IF(E9="",0,E9)-IF(F9="",0,F9)) -> 0
A10: QAT8 | B10: Tarek Salman | C10: X | E10: 1 | F10: 1 | G10: =MAX(0,IF(E10="",0,E10)-IF(F10="",0,F10)) -> 0
A11: QAT9 | B11: Mohammed Mannai | C11: X | E11: 2 | F11: 2 | G11: =MAX(0,IF(E11="",0,E11)-IF(F11="",0,F11)) -> 0
A12: QAT10 | B12: Karim Boudiaf | C12: X | E12: 1 | F12: 1 | G12: =MAX(0,IF(E12="",0,E12)-IF(F12="",0,F12)) -> 0
A13: QAT11 | B13: Assim Madibo | C13: X | G13: =MAX(0,IF(E13="",0,E13)-IF(F13="",0,F13)) -> 0
A14: QAT12 | B14: Hamed Fatehi | C14: X | G14: =MAX(0,IF(E14="",0,E14)-IF(F14="",0,F14)) -> 0
A15: QAT13 | B15: Foto Equipo | C15: X | G15: =MAX(0,IF(E15="",0,E15)-IF(F15="",0,F15)) -> 0
A16: QAT14 | B16: Mohammed Waad | C16: X | G16: =MAX(0,IF(E16="",0,E16)-IF(F16="",0,F16)) -> 0
A17: QAT15 | B17: Abdulaziz Hatem | C17: X | G17: =MAX(0,IF(E17="",0,E17)-IF(F17="",0,F17)) -> 0
A18: QAT16 | B18: Hassan Al-Haydos | C18: X | G18: =MAX(0,IF(E18="",0,E18)-IF(F18="",0,F18)) -> 0
A19: QAT17 | B19: Edmilson Junior | C19: X | E19: 3 | F19: 3 | G19: =MAX(0,IF(E19="",0,E19)-IF(F19="",0,F19)) -> 0
A20: QAT18 | B20: Akram Hassan Afif | C20: X | E20: 1 | F20: 1 | G20: =MAX(0,IF(E20="",0,E20)-IF(F20="",0,F20)) -> 0
A21: QAT19 | B21: Ahmed Al-Ganehi | C21: X | G21: =MAX(0,IF(E21="",0,E21)-IF(F21="",0,F21)) -> 0
A22: QAT20 | B22: Almoez Ali | C22: X | G22: =MAX(0,IF(E22="",0,E22)-IF(F22="",0,F22)) -> 0

Sheet GRUPO B · Switzerland
A1: GRUPO B · Switzerland
A2: Código | B2: Jugador / Cromo | C2: Tengo | D2: Pedir | E2: Repetidos | F2: Enviados | G2: Disponibles
A3: SUI1 | B3: Escudo | C3: X | E3: 1 | F3: 1 | G3: =MAX(0,IF(E3="",0,E3)-IF(F3="",0,F3)) -> 0
A4: SUI2 | B4: Gregor Kobel | C4: X | G4: =MAX(0,IF(E4="",0,E4)-IF(F4="",0,F4)) -> 0
A5: SUI3 | B5: Yvon Mvogo | C5: X | E5: 1 | F5: 1 | G5: =MAX(0,IF(E5="",0,E5)-IF(F5="",0,F5)) -> 0
A6: SUI4 | B6: Manuel Akanji | C6: X | E6: 2 | F6: 2 | G6: =MAX(0,IF(E6="",0,E6)-IF(F6="",0,F6)) -> 0
A7: SUI5 | B7: Ricardo Rodríguez | C7: X | E7: 1 | F7: 1 | G7: =MAX(0,IF(E7="",0,E7)-IF(F7="",0,F7)) -> 0
A8: SUI6 | B8: Nico Elvedi | C8: X | E8: 1 | F8: 1 | G8: =MAX(0,IF(E8="",0,E8)-IF(F8="",0,F8)) -> 0
A9: SUI7 | B9: Aurèle Amenda | C9: X | G9: =MAX(0,IF(E9="",0,E9)-IF(F9="",0,F9)) -> 0
A10: SUI8 | B10: Silvan Widmer | C10: X | G10: =MAX(0,IF(E10="",0,E10)-IF(F10="",0,F10)) -> 0
A11: SUI9 | B11: Granit Xhaka | C11: X | G11: =MAX(0,IF(E11="",0,E11)-IF(F11="",0,F11)) -> 0
A12: SUI10 | B12: Denis Zakaria | C12: X | E12: 1 | F12: 1 | G12: =MAX(0,IF(E12="",0,E12)-IF(F12="",0,F12)) -> 0
A13: SUI11 | B13: Remo Freuler | C13: X | G13: =MAX(0,IF(E13="",0,E13)-IF(F13="",0,F13)) -> 0
A14: SUI12 | B14: Fabian Rieder | C14: X | G14: =MAX(0,IF(E14="",0,E14)-IF(F14="",0,F14)) -> 0
A15: SUI13 | B15: Foto Equipo | C15: X | E15: 1 | F15: 1 | G15: =MAX(0,IF(E15="",0,E15)-IF(F15="",0,F15)) -> 0
A16: SUI14 | B16: Ardon Jashari | C16: X | G16: =MAX(0,IF(E16="",0,E16)-IF(F16="",0,F16)) -> 0
A17: SUI15 | B17: Johan Manzambi | C17: X | E17: 1 | F17: 1 | G17: =MAX(0,IF(E17="",0,E17)-IF(F17="",0,F17)) -> 0
A18: SUI16 | B18: Michel Aebischer | C18: X | G18: =MAX(0,IF(E18="",0,E18)-IF(F18="",0,F18)) -> 0
A19: SUI17 | B19: Breel Embolo | C19: X | G19: =MAX(0,IF(E19="",0,E19)-IF(F19="",0,F19)) -> 0
A20: SUI18 | B20: Rubén Vargas | C20: X | E20: 1 | F20: 1 | G20: =MAX(0,IF(E20="",0,E20)-IF(F20="",0,F20)) -> 0
A21: SUI19 | B21: Dan Ndoye | C21: X | E21: 2 | F21: 2 | G21: =MAX(0,IF(E21="",0,E21)-IF(F21="",0,F21)) -> 0
A22: SUI20 | B22: Zeki Amdouni | C22: X | E22: 2 | F22: 2 | G22: =MAX(0,IF(E22="",0,E22)-IF(F22="",0,F22)) -> 0

Sheet GRUPO C · Brazil
A1: GRUPO C · Brazil
A2: Código | B2: Jugador / Cromo | C2: Tengo | D2: Pedir | E2: Repetidos | F2: Enviados | G2: Disponibles
A3: BRA1 | B3: Escudo | C3: X | E3: 1 | F3: 1 | G3: =MAX(0,IF(E3="",0,E3)-IF(F3="",0,F3)) -> 0
A4: BRA2 | B4: Alisson | C4: X | G4: =MAX(0,IF(E4="",0,E4)-IF(F4="",0,F4)) -> 0
A5: BRA3 | B5: Bento | C5: X | E5: 2 | F5: 2 | G5: =MAX(0,IF(E5="",0,E5)-IF(F5="",0,F5)) -> 0
A6: BRA4 | B6: Marquinhos | C6: X | G6: =MAX(0,IF(E6="",0,E6)-IF(F6="",0,F6)) -> 0
A7: BRA5 | B7: Éder Militão | C7: X | E7: 1 | F7: 1 | G7: =MAX(0,IF(E7="",0,E7)-IF(F7="",0,F7)) -> 0
A8: BRA6 | B8: Gabriel Magalhães | C8: X | E8: 1 | F8: 1 | G8: =MAX(0,IF(E8="",0,E8)-IF(F8="",0,F8)) -> 0
A9: BRA7 | B9: Danilo | C9: X | G9: =MAX(0,IF(E9="",0,E9)-IF(F9="",0,F9)) -> 0
A10: BRA8 | B10: Wesley | C10: X | E10: 1 | F10: 1 | G10: =MAX(0,IF(E10="",0,E10)-IF(F10="",0,F10)) -> 0
A11: BRA9 | B11: Lucas Paquetá | C11: X | E11: 3 | F11: 3 | G11: =MAX(0,IF(E11="",0,E11)-IF(F11="",0,F11)) -> 0
A12: BRA10 | B12: Casemiro | C12: X | G12: =MAX(0,IF(E12="",0,E12)-IF(F12="",0,F12)) -> 0
A13: BRA11 | B13: Bruno Guimarães | C13: X | G13: =MAX(0,IF(E13="",0,E13)-IF(F13="",0,F13)) -> 0
A14: BRA12 | B14: Luiz Henrique | C14: X | G14: =MAX(0,IF(E14="",0,E14)-IF(F14="",0,F14)) -> 0
A15: BRA13 | B15: Foto Equipo | C15: X | E15: 1 | F15: 1 | G15: =MAX(0,IF(E15="",0,E15)-IF(F15="",0,F15)) -> 0
A16: BRA14 | B16: Vinicius Júnior | C16: X | G16: =MAX(0,IF(E16="",0,E16)-IF(F16="",0,F16)) -> 0
A17: BRA15 | B17: Rodrygo | C17: X | E17: 1 | F17: 1 | G17: =MAX(0,IF(E17="",0,E17)-IF(F17="",0,F17)) -> 0
A18: BRA16 | B18: João Pedro | C18: X | E18: 2 | F18: 2 | G18: =MAX(0,IF(E18="",0,E18)-IF(F18="",0,F18)) -> 0
A19: BRA17 | B19: Matheus Cunha | C19: X | E19: 1 | F19: 1 | G19: =MAX(0,IF(E19="",0,E19)-IF(F19="",0,F19)) -> 0
A20: BRA18 | B20: Gabriel Martinelli | C20: X | G20: =MAX(0,IF(E20="",0,E20)-IF(F20="",0,F20)) -> 0
A21: BRA19 | B21: Raphinha | C21: X | E21: 2 | F21: 2 | G21: =MAX(0,IF(E21="",0,E21)-IF(F21="",0,F21)) -> 0
A22: BRA20 | B22: Estévão | C22: X | E22: 1 | F22: 1 | G22: =MAX(0,IF(E22="",0,E22)-IF(F22="",0,F22)) -> 0

Sheet GRUPO C · Morocco
A1: GRUPO C · Morocco
A2: Código | B2: Jugador / Cromo | C2: Tengo | D2: Pedir | E2: Repetidos | F2: Enviados | G2: Disponibles
A3: MAR1 | B3: Escudo | C3: X | G3: =MAX(0,IF(E3="",0,E3)-IF(F3="",0,F3)) -> 0
A4: MAR2 | B4: Yassine Bounou | C4: X | E4: 1 | F4: 1 | G4: =MAX(0,IF(E4="",0,E4)-IF(F4="",0,F4)) -> 0
A5: MAR3 | B5: Munir El Kajoui | C5: X | G5: =MAX(0,IF(E5="",0,E5)-IF(F5="",0,F5)) -> 0
A6: MAR4 | B6: Achraf Hakimi | C6: X | E6: 1 | F6: 1 | G6: =MAX(0,IF(E6="",0,E6)-IF(F6="",0,F6)) -> 0
A7: MAR5 | B7: Noussair Mazraoui | C7: X | E7: 2 | F7: 2 | G7: =MAX(0,IF(E7="",0,E7)-IF(F7="",0,F7)) -> 0
A8: MAR6 | B8: Nayef Aguerd | C8: X | E8: 3 | F8: 3 | G8: =MAX(0,IF(E8="",0,E8)-IF(F8="",0,F8)) -> 0
A9: MAR7 | B9: Romain Saïss | C9: X | G9: =MAX(0,IF(E9="",0,E9)-IF(F9="",0,F9)) -> 0
A10: MAR8 | B10: Jawad El Yamiq | C10: X | G10: =MAX(0,IF(E10="",0,E10)-IF(F10="",0,F10)) -> 0
A11: MAR9 | B11: Adam Masina | C11: X | G11: =MAX(0,IF(E11="",0,E11)-IF(F11="",0,F11)) -> 0
A12: MAR10 | B12: Sofyan Amrabat | C12: X | G12: =MAX(0,IF(E12="",0,E12)-IF(F12="",0,F12)) -> 0
A13: MAR11 | B13: Azzedine Ounahi | C13: X | G13: =MAX(0,IF(E13="",0,E13)-IF(F13="",0,F13)) -> 0
A14: MAR12 | B14: Eliesse Ben Seghir | C14: X | E14: 1 | F14: 1 | G14: =MAX(0,IF(E14="",0,E14)-IF(F14="",0,F14)) -> 0
A15: MAR13 | B15: Foto Equipo | C15: X | E15: 1 | F15: 1 | G15: =MAX(0,IF(E15="",0,E15)-IF(F15="",0,F15)) -> 0
A16: MAR14 | B16: Bilal El Khannouss | C16: X | E16: 1 | F16: 1 | G16: =MAX(0,IF(E16="",0,E16)-IF(F16="",0,F16)) -> 0
A17: MAR15 | B17: Ismael Saibari | C17: X | G17: =MAX(0,IF(E17="",0,E17)-IF(F17="",0,F17)) -> 0
A18: MAR16 | B18: Youssef En-Nesyri | C18: X | G18: =MAX(0,IF(E18="",0,E18)-IF(F18="",0,F18)) -> 0
A19: MAR17 | B19: Abde Ezzalzouli | C19: X | E19: 1 | F19: 1 | G19: =MAX(0,IF(E19="",0,E19)-IF(F19="",0,F19)) -> 0
A20: MAR18 | B20: Soufiane Rahimi | C20: X | G20: =MAX(0,IF(E20="",0,E20)-IF(F20="",0,F20)) -> 0
A21: MAR19 | B21: Brahim Díaz | C21: X | E21: 1 | F21: 1 | G21: =MAX(0,IF(E21="",0,E21)-IF(F21="",0,F21)) -> 0
A22: MAR20 | B22: Ayoub El Kaabi | C22: X | G22: =MAX(0,IF(E22="",0,E22)-IF(F22="",0,F22)) -> 0

Sheet GRUPO C · Haiti
A1: GRUPO C · Haiti
A2: Código | B2: Jugador / Cromo | C2: Tengo | D2: Pedir | E2: Repetidos | F2: Enviados | G2: Disponibles
A3: HAI1 | B3: Escudo | C3: X | E3: 1 | F3: 1 | G3: =MAX(0,IF(E3="",0,E3)-IF(F3="",0,F3)) -> 0
A4: HAI2 | B4: Johny Placide | C4: X | E4: 1 | F4: 1 | G4: =MAX(0,IF(E4="",0,E4)-IF(F4="",0,F4)) -> 0
A5: HAI3 | B5: Carlens Arcus | C5: X | E5: 1 | F5: 1 | G5: =MAX(0,IF(E5="",0,E5)-IF(F5="",0,F5)) -> 0
A6: HAI4 | B6: Martin Expérience | C6: X | E6: 1 | F6: 1 | G6: =MAX(0,IF(E6="",0,E6)-IF(F6="",0,F6)) -> 0
A7: HAI5 | B7: Jean-Kévin Duverne | C7: X | E7: 1 | F7: 1 | G7: =MAX(0,IF(E7="",0,E7)-IF(F7="",0,F7)) -> 0
A8: HAI6 | B8: Ricardo Adé | C8: X | E8: 1 | F8: 1 | G8: =MAX(0,IF(E8="",0,E8)-IF(F8="",0,F8)) -> 0
A9: HAI7 | B9: Duke Lacroix | C9: X | G9: =MAX(0,IF(E9="",0,E9)-IF(F9="",0,F9)) -> 0
A10: HAI8 | B10: Garven Metusala | C10: X | E10: 2 | F10: 2 | G10: =MAX(0,IF(E10="",0,E10)-IF(F10="",0,F10)) -> 0
A11: HAI9 | B11: Hannes Delcroix | C11: X | G11: =MAX(0,IF(E11="",0,E11)-IF(F11="",0,F11)) -> 0
A12: HAI10 | B12: Leverton Pierre | C12: X | E12: 1 | F12: 1 | G12: =MAX(0,IF(E12="",0,E12)-IF(F12="",0,F12)) -> 0
A13: HAI11 | B13: Danley Jean Jacques | C13: X | G13: =MAX(0,IF(E13="",0,E13)-IF(F13="",0,F13)) -> 0
A14: HAI12 | B14: Jean-Ricner Bellegarde | C14: X | G14: =MAX(0,IF(E14="",0,E14)-IF(F14="",0,F14)) -> 0
A15: HAI13 | B15: Foto Equipo | C15: X | G15: =MAX(0,IF(E15="",0,E15)-IF(F15="",0,F15)) -> 0
A16: HAI14 | B16: Christopher Attys | C16: X | G16: =MAX(0,IF(E16="",0,E16)-IF(F16="",0,F16)) -> 0
A17: HAI15 | B17: Derrick Etienne Jr. | C17: X | G17: =MAX(0,IF(E17="",0,E17)-IF(F17="",0,F17)) -> 0
A18: HAI16 | B18: Josué Casimir | C18: X | E18: 1 | F18: 1 | G18: =MAX(0,IF(E18="",0,E18)-IF(F18="",0,F18)) -> 0
A19: HAI17 | B19: Ruben Providence | C19: X | E19: 1 | F19: 1 | G19: =MAX(0,IF(E19="",0,E19)-IF(F19="",0,F19)) -> 0
A20: HAI18 | B20: Duckens Nazon | C20: X | G20: =MAX(0,IF(E20="",0,E20)-IF(F20="",0,F20)) -> 0
A21: HAI19 | B21: Louicius Deedson | C21: X | E21: 1 | F21: 1 | G21: =MAX(0,IF(E21="",0,E21)-IF(F21="",0,F21)) -> 0
A22: HAI20 | B22: Frantzdy Pierrot | C22: X | E22: 3 | F22: 3 | G22: =MAX(0,IF(E22="",0,E22)-IF(F22="",0,F22)) -> 0

Sheet GRUPO C · Scotland
A1: GRUPO C · Scotland
A2: Código | B2: Jugador / Cromo | C2: Tengo | D2: Pedir | E2: Repetidos | F2: Enviados | G2: Disponibles
A3: SCO1 | B3: Escudo | C3: X | G3: =MAX(0,IF(E3="",0,E3)-IF(F3="",0,F3)) -> 0
A4: SCO2 | B4: Angus Gunn | C4: X | E4: 1 | F4: 1 | G4: =MAX(0,IF(E4="",0,E4)-IF(F4="",0,F4)) -> 0
A5: SCO3 | B5: Jack Hendry | C5: X | E5: 2 | F5: 2 | G5: =MAX(0,IF(E5="",0,E5)-IF(F5="",0,F5)) -> 0
A6: SCO4 | B6: Kieran Tierney | C6: X | G6: =MAX(0,IF(E6="",0,E6)-IF(F6="",0,F6)) -> 0
A7: SCO5 | B7: Aaron Hickey | C7: X | G7: =MAX(0,IF(E7="",0,E7)-IF(F7="",0,F7)) -> 0
A8: SCO6 | B8: Andrew Robertson | C8: X | E8: 2 | F8: 2 | G8: =MAX(0,IF(E8="",0,E8)-IF(F8="",0,F8)) -> 0
A9: SCO7 | B9: Scott McKenna | C9: X | G9: =MAX(0,IF(E9="",0,E9)-IF(F9="",0,F9)) -> 0
A10: SCO8 | B10: John Souttar | C10: X | E10: 3 | F10: 3 | G10: =MAX(0,IF(E10="",0,E10)-IF(F10="",0,F10)) -> 0
A11: SCO9 | B11: Anthony Ralston | C11: X | E11: 2 | F11: 2 | G11: =MAX(0,IF(E11="",0,E11)-IF(F11="",0,F11)) -> 0
A12: SCO10 | B12: Grant Hanley | C12: X | G12: =MAX(0,IF(E12="",0,E12)-IF(F12="",0,F12)) -> 0
A13: SCO11 | B13: Scott McTominay | C13: X | E13: 1 | F13: 1 | G13: =MAX(0,IF(E13="",0,E13)-IF(F13="",0,F13)) -> 0
A14: SCO12 | B14: Billy Gilmour | C14: X | G14: =MAX(0,IF(E14="",0,E14)-IF(F14="",0,F14)) -> 0
A15: SCO13 | B15: Foto Equipo | C15: X | E15: 3 | F15: 3 | G15: =MAX(0,IF(E15="",0,E15)-IF(F15="",0,F15)) -> 0
A16: SCO14 | B16: Lewis Ferguson | C16: X | G16: =MAX(0,IF(E16="",0,E16)-IF(F16="",0,F16)) -> 0
A17: SCO15 | B17: Ryan Christie | C17: X | E17: 1 | F17: 1 | G17: =MAX(0,IF(E17="",0,E17)-IF(F17="",0,F17)) -> 0
A18: SCO16 | B18: Kenny McLean | C18: X | G18: =MAX(0,IF(E18="",0,E18)-IF(F18="",0,F18)) -> 0
A19: SCO17 | B19: John McGinn | C19: X | E19: 2 | F19: 2 | G19: =MAX(0,IF(E19="",0,E19)-IF(F19="",0,F19)) -> 0
A20: SCO18 | B20: Lyndon Dykes | C20: X | E20: 2 | F20: 2 | G20: =MAX(0,IF(E20="",0,E20)-IF(F20="",0,F20)) -> 0
A21: SCO19 | B21: Ché Adams | C21: X | E21: 1 | F21: 1 | G21: =MAX(0,IF(E21="",0,E21)-IF(F21="",0,F21)) -> 0
A22: SCO20 | B22: Ben Gannon-Doak | C22: X | G22: =MAX(0,IF(E22="",0,E22)-IF(F22="",0,F22)) -> 0

Sheet GRUPO D · USA
A1: GRUPO D · USA
A2: Código | B2: Jugador / Cromo | C2: Tengo | D2: Pedir | E2: Repetidos | F2: Enviados | G2: Disponibles
A3: USA1 | B3: Escudo | C3: X | E3: 1 | F3: 1 | G3: =MAX(0,IF(E3="",0,E3)-IF(F3="",0,F3)) -> 0
A4: USA2 | B4: Matt Freese | C4: X | G4: =MAX(0,IF(E4="",0,E4)-IF(F4="",0,F4)) -> 0
A5: USA3 | B5: Chris Richards | C5: X | G5: =MAX(0,IF(E5="",0,E5)-IF(F5="",0,F5)) -> 0
A6: USA4 | B6: Tim Ream | C6: X | G6: =MAX(0,IF(E6="",0,E6)-IF(F6="",0,F6)) -> 0
A7: USA5 | B7: Mark McKenzie | C7: X | G7: =MAX(0,IF(E7="",0,E7)-IF(F7="",0,F7)) -> 0
A8: USA6 | B8: Alex Freeman | C8: X | G8: =MAX(0,IF(E8="",0,E8)-IF(F8="",0,F8)) -> 0
A9: USA7 | B9: Antonee Robinson | C9: X | G9: =MAX(0,IF(E9="",0,E9)-IF(F9="",0,F9)) -> 0
A10: USA8 | B10: Tyler Adams | C10: X | G10: =MAX(0,IF(E10="",0,E10)-IF(F10="",0,F10)) -> 0
A11: USA9 | B11: Tanner Tessmann | C11: X | G11: =MAX(0,IF(E11="",0,E11)-IF(F11="",0,F11)) -> 0
A12: USA10 | B12: Weston McKennie | C12: X | E12: 1 | F12: 1 | G12: =MAX(0,IF(E12="",0,E12)-IF(F12="",0,F12)) -> 0
A13: USA11 | B13: Christian Roldan | C13: X | G13: =MAX(0,IF(E13="",0,E13)-IF(F13="",0,F13)) -> 0
A14: USA12 | B14: Timothy Weah | C14: X | E14: 2 | F14: 2 | G14: =MAX(0,IF(E14="",0,E14)-IF(F14="",0,F14)) -> 0
A15: USA13 | B15: Foto Equipo | C15: X | E15: 3 | F15: 3 | G15: =MAX(0,IF(E15="",0,E15)-IF(F15="",0,F15)) -> 0
A16: USA14 | B16: Diego Luna | C16: X | E16: 3 | F16: 3 | G16: =MAX(0,IF(E16="",0,E16)-IF(F16="",0,F16)) -> 0
A17: USA15 | B17: Malik Tillman | C17: X | G17: =MAX(0,IF(E17="",0,E17)-IF(F17="",0,F17)) -> 0
A18: USA16 | B18: Christian Pulisic | C18: X | E18: 1 | F18: 1 | G18: =MAX(0,IF(E18="",0,E18)-IF(F18="",0,F18)) -> 0
A19: USA17 | B19: Brenden Aaronson | C19: X | E19: 1 | F19: 1 | G19: =MAX(0,IF(E19="",0,E19)-IF(F19="",0,F19)) -> 0
A20: USA18 | B20: Ricardo Pepi | C20: X | G20: =MAX(0,IF(E20="",0,E20)-IF(F20="",0,F20)) -> 0
A21: USA19 | B21: Haji Wright | C21: X | E21: 1 | F21: 1 | G21: =MAX(0,IF(E21="",0,E21)-IF(F21="",0,F21)) -> 0
A22: USA20 | B22: Folarin Balogun | C22: X | E22: 1 | F22: 1 | G22: =MAX(0,IF(E22="",0,E22)-IF(F22="",0,F22)) -> 0

Sheet GRUPO D · Paraguay
A1: GRUPO D · Paraguay
A2: Código | B2: Jugador / Cromo | C2: Tengo | D2: Pedir | E2: Repetidos | F2: Enviados | G2: Disponibles
A3: PAR1 | B3: Escudo | C3: X | E3: 4 | F3: 4 | G3: =MAX(0,IF(E3="",0,E3)-IF(F3="",0,F3)) -> 0
A4: PAR2 | B4: Roberto Fernández | C4: X | G4: =MAX(0,IF(E4="",0,E4)-IF(F4="",0,F4)) -> 0
A5: PAR3 | B5: Orlando Gill | C5: X | G5: =MAX(0,IF(E5="",0,E5)-IF(F5="",0,F5)) -> 0
A6: PAR4 | B6: Gustavo Gómez | C6: X | G6: =MAX(0,IF(E6="",0,E6)-IF(F6="",0,F6)) -> 0
A7: PAR5 | B7: Fabián Balbuena | C7: X | E7: 1 | F7: 1 | G7: =MAX(0,IF(E7="",0,E7)-IF(F7="",0,F7)) -> 0
A8: PAR6 | B8: Juan José Cáceres | C8: X | E8: 1 | F8: 1 | G8: =MAX(0,IF(E8="",0,E8)-IF(F8="",0,F8)) -> 0
A9: PAR7 | B9: Omar Alderete | C9: X | E9: 3 | F9: 3 | G9: =MAX(0,IF(E9="",0,E9)-IF(F9="",0,F9)) -> 0
A10: PAR8 | B10: Júnior Alonso | C10: X | G10: =MAX(0,IF(E10="",0,E10)-IF(F10="",0,F10)) -> 0
A11: PAR9 | B11: Mathías Villasanti | C11: X | E11: 2 | F11: 2 | G11: =MAX(0,IF(E11="",0,E11)-IF(F11="",0,F11)) -> 0
A12: PAR10 | B12: Diego Gómez | C12: X | G12: =MAX(0,IF(E12="",0,E12)-IF(F12="",0,F12)) -> 0
A13: PAR11 | B13: Damián Bobadilla | C13: X | E13: 2 | F13: 2 | G13: =MAX(0,IF(E13="",0,E13)-IF(F13="",0,F13)) -> 0
A14: PAR12 | B14: Andrés Cubas | C14: X | G14: =MAX(0,IF(E14="",0,E14)-IF(F14="",0,F14)) -> 0
A15: PAR13 | B15: Foto Equipo | C15: X | G15: =MAX(0,IF(E15="",0,E15)-IF(F15="",0,F15)) -> 0
A16: PAR14 | B16: Matías Galarza Fonda | C16: X | G16: =MAX(0,IF(E16="",0,E16)-IF(F16="",0,F16)) -> 0
A17: PAR15 | B17: Julio Enciso | C17: X | E17: 1 | F17: 1 | G17: =MAX(0,IF(E17="",0,E17)-IF(F17="",0,F17)) -> 0
A18: PAR16 | B18: Alejandro Romero Gamarra | C18: X | E18: 1 | F18: 1 | G18: =MAX(0,IF(E18="",0,E18)-IF(F18="",0,F18)) -> 0
A19: PAR17 | B19: Miguel Almirón | C19: X | E19: 1 | F19: 1 | G19: =MAX(0,IF(E19="",0,E19)-IF(F19="",0,F19)) -> 0
A20: PAR18 | B20: Ramón Sosa | C20: X | G20: =MAX(0,IF(E20="",0,E20)-IF(F20="",0,F20)) -> 0
A21: PAR19 | B21: Ángel Romero | C21: X | G21: =MAX(0,IF(E21="",0,E21)-IF(F21="",0,F21)) -> 0
A22: PAR20 | B22: Antonio Sanabria | C22: X | E22: 1 | F22: 1 | G22: =MAX(0,IF(E22="",0,E22)-IF(F22="",0,F22)) -> 0

Sheet GRUPO D · Australia
A1: GRUPO D · Australia
A2: Código | B2: Jugador / Cromo | C2: Tengo | D2: Pedir | E2: Repetidos | F2: Enviados | G2: Disponibles
A3: AUS1 | B3: Escudo | C3: X | G3: =MAX(0,IF(E3="",0,E3)-IF(F3="",0,F3)) -> 0
A4: AUS2 | B4: Mathew Ryan | C4: X | E4: 1 | F4: 1 | G4: =MAX(0,IF(E4="",0,E4)-IF(F4="",0,F4)) -> 0
A5: AUS3 | B5: Joe Gauci | C5: X | G5: =MAX(0,IF(E5="",0,E5)-IF(F5="",0,F5)) -> 0
A6: AUS4 | B6: Harry Souttar | C6: X | G6: =MAX(0,IF(E6="",0,E6)-IF(F6="",0,F6)) -> 0
A7: AUS5 | B7: Alessandro Circati | C7: X | E7: 1 | F7: 1 | G7: =MAX(0,IF(E7="",0,E7)-IF(F7="",0,F7)) -> 0
A8: AUS6 | B8: Jordan Bos | C8: X | G8: =MAX(0,IF(E8="",0,E8)-IF(F8="",0,F8)) -> 0
A9: AUS7 | B9: Aziz Behich | C9: X | E9: 1 | F9: 1 | G9: =MAX(0,IF(E9="",0,E9)-IF(F9="",0,F9)) -> 0
A10: AUS8 | B10: Cameron Burgess | C10: X | G10: =MAX(0,IF(E10="",0,E10)-IF(F10="",0,F10)) -> 0
A11: AUS9 | B11: Lewis Miller | C11: X | G11: =MAX(0,IF(E11="",0,E11)-IF(F11="",0,F11)) -> 0
A12: AUS10 | B12: Milos Degenek | C12: X | E12: 1 | F12: 1 | G12: =MAX(0,IF(E12="",0,E12)-IF(F12="",0,F12)) -> 0
A13: AUS11 | B13: Jackson Irvine | C13: X | E13: 2 | F13: 2 | G13: =MAX(0,IF(E13="",0,E13)-IF(F13="",0,F13)) -> 0
A14: AUS12 | B14: Riley McGree | C14: X | G14: =MAX(0,IF(E14="",0,E14)-IF(F14="",0,F14)) -> 0
A15: AUS13 | B15: Foto Equipo | C15: X | E15: 1 | F15: 1 | G15: =MAX(0,IF(E15="",0,E15)-IF(F15="",0,F15)) -> 0
A16: AUS14 | B16: Aiden O'Neill | C16: X | E16: 1 | F16: 1 | G16: =MAX(0,IF(E16="",0,E16)-IF(F16="",0,F16)) -> 0
A17: AUS15 | B17: Connor Metcalfe | C17: X | E17: 1 | F17: 1 | G17: =MAX(0,IF(E17="",0,E17)-IF(F17="",0,F17)) -> 0
A18: AUS16 | B18: Patrick Yazbek | C18: X | G18: =MAX(0,IF(E18="",0,E18)-IF(F18="",0,F18)) -> 0
A19: AUS17 | B19: Craig Goodwin | C19: X | E19: 2 | F19: 2 | G19: =MAX(0,IF(E19="",0,E19)-IF(F19="",0,F19)) -> 0
A20: AUS18 | B20: Kusini Yengi | C20: X | E20: 2 | F20: 2 | G20: =MAX(0,IF(E20="",0,E20)-IF(F20="",0,F20)) -> 0
A21: AUS19 | B21: Nestory Irankunda | C21: X | E21: 3 | F21: 3 | G21: =MAX(0,IF(E21="",0,E21)-IF(F21="",0,F21)) -> 0
A22: AUS20 | B22: Mohamed Touré | C22: X | G22: =MAX(0,IF(E22="",0,E22)-IF(F22="",0,F22)) -> 0

Sheet GRUPO D · Türkiye
A1: GRUPO D · Türkiye
A2: Código | B2: Jugador / Cromo | C2: Tengo | D2: Pedir | E2: Repetidos | F2: Enviados | G2: Disponibles
A3: TUR1 | B3: Escudo | C3: X | E3: 2 | F3: 2 | G3: =MAX(0,IF(E3="",0,E3)-IF(F3="",0,F3)) -> 0
A4: TUR2 | B4: Uğurcan Çakır | C4: X | E4: 1 | F4: 1 | G4: =MAX(0,IF(E4="",0,E4)-IF(F4="",0,F4)) -> 0
A5: TUR3 | B5: Mert Müldür | C5: X | G5: =MAX(0,IF(E5="",0,E5)-IF(F5="",0,F5)) -> 0
A6: TUR4 | B6: Zeki Çelik | C6: X | G6: =MAX(0,IF(E6="",0,E6)-IF(F6="",0,F6)) -> 0
A7: TUR5 | B7: Abdülkerim Bardakçı | C7: X | G7: =MAX(0,IF(E7="",0,E7)-IF(F7="",0,F7)) -> 0
A8: TUR6 | B8: Çağlar Söyüncü | C8: X | G8: =MAX(0,IF(E8="",0,E8)-IF(F8="",0,F8)) -> 0
A9: TUR7 | B9: Merih Demiral | C9: X | E9: 2 | F9: 2 | G9: =MAX(0,IF(E9="",0,E9)-IF(F9="",0,F9)) -> 0
A10: TUR8 | B10: Ferdi Kadıoğlu | C10: X | E10: 2 | F10: 2 | G10: =MAX(0,IF(E10="",0,E10)-IF(F10="",0,F10)) -> 0
A11: TUR9 | B11: Kaan Ayhan | C11: X | E11: 1 | F11: 1 | G11: =MAX(0,IF(E11="",0,E11)-IF(F11="",0,F11)) -> 0
A12: TUR10 | B12: Ismail Yüksek | C12: X | G12: =MAX(0,IF(E12="",0,E12)-IF(F12="",0,F12)) -> 0
A13: TUR11 | B13: Hakan Çalhanoğlu | C13: X | G13: =MAX(0,IF(E13="",0,E13)-IF(F13="",0,F13)) -> 0
A14: TUR12 | B14: Orkun Kökçü | C14: X | E14: 3 | F14: 3 | G14: =MAX(0,IF(E14="",0,E14)-IF(F14="",0,F14)) -> 0
A15: TUR13 | B15: Foto Equipo | C15: X | G15: =MAX(0,IF(E15="",0,E15)-IF(F15="",0,F15)) -> 0
A16: TUR14 | B16: Arda Güler | C16: X | G16: =MAX(0,IF(E16="",0,E16)-IF(F16="",0,F16)) -> 0
A17: TUR15 | B17: Irfan Can Kahveci | C17: X | G17: =MAX(0,IF(E17="",0,E17)-IF(F17="",0,F17)) -> 0
A18: TUR16 | B18: Yunus Akgün | C18: X | E18: 1 | F18: 1 | G18: =MAX(0,IF(E18="",0,E18)-IF(F18="",0,F18)) -> 0
A19: TUR17 | B19: Can Uzun | C19: X | G19: =MAX(0,IF(E19="",0,E19)-IF(F19="",0,F19)) -> 0
A20: TUR18 | B20: Barış Alper Yılmaz | C20: X | E20: 1 | F20: 1 | G20: =MAX(0,IF(E20="",0,E20)-IF(F20="",0,F20)) -> 0
A21: TUR19 | B21: Kerem Aktürkoğlu | C21: X | E21: 2 | F21: 2 | G21: =MAX(0,IF(E21="",0,E21)-IF(F21="",0,F21)) -> 0
A22: TUR20 | B22: Kenan Yildiz | C22: X | G22: =MAX(0,IF(E22="",0,E22)-IF(F22="",0,F22)) -> 0

Sheet GRUPO E · Germany
A1: GRUPO E · Germany
A2: Código | B2: Jugador / Cromo | C2: Tengo | D2: Pedir | E2: Repetidos | F2: Enviados | G2: Disponibles
A3: GER1 | B3: Escudo | C3: X | E3: 1 | F3: 1 | G3: =MAX(0,IF(E3="",0,E3)-IF(F3="",0,F3)) -> 0
A4: GER2 | B4: Marc-André ter Stegen | C4: X | E4: 2 | F4: 2 | G4: =MAX(0,IF(E4="",0,E4)-IF(F4="",0,F4)) -> 0
A5: GER3 | B5: Jonathan Tah | C5: X | E5: 1 | F5: 1 | G5: =MAX(0,IF(E5="",0,E5)-IF(F5="",0,F5)) -> 0
A6: GER4 | B6: David Raum | C6: X | G6: =MAX(0,IF(E6="",0,E6)-IF(F6="",0,F6)) -> 0
A7: GER5 | B7: Nico Schlotterbeck | C7: X | G7: =MAX(0,IF(E7="",0,E7)-IF(F7="",0,F7)) -> 0
A8: GER6 | B8: Antonio Rüdiger | C8: X | G8: =MAX(0,IF(E8="",0,E8)-IF(F8="",0,F8)) -> 0
A9: GER7 | B9: Waldemar Anton | C9: X | E9: 2 | F9: 2 | G9: =MAX(0,IF(E9="",0,E9)-IF(F9="",0,F9)) -> 0
A10: GER8 | B10: Ridle Baku | C10: X | G10: =MAX(0,IF(E10="",0,E10)-IF(F10="",0,F10)) -> 0
A11: GER9 | B11: Maximilian Mittelstadt | C11: X | E11: 1 | F11: 1 | G11: =MAX(0,IF(E11="",0,E11)-IF(F11="",0,F11)) -> 0
A12: GER10 | B12: Joshua Kimmich | C12: X | E12: 1 | F12: 1 | G12: =MAX(0,IF(E12="",0,E12)-IF(F12="",0,F12)) -> 0
A13: GER11 | B13: Florian Wirtz | C13: X | E13: 1 | F13: 1 | G13: =MAX(0,IF(E13="",0,E13)-IF(F13="",0,F13)) -> 0
A14: GER12 | B14: Felix Nmecha | C14: X | E14: 3 | F14: 3 | G14: =MAX(0,IF(E14="",0,E14)-IF(F14="",0,F14)) -> 0
A15: GER13 | B15: Foto Equipo | C15: X | G15: =MAX(0,IF(E15="",0,E15)-IF(F15="",0,F15)) -> 0
A16: GER14 | B16: Leon Goretzka | C16: X | E16: 4 | F16: 4 | G16: =MAX(0,IF(E16="",0,E16)-IF(F16="",0,F16)) -> 0
A17: GER15 | B17: Jamal Musiala | C17: X | E17: 1 | F17: 1 | G17: =MAX(0,IF(E17="",0,E17)-IF(F17="",0,F17)) -> 0
A18: GER16 | B18: Serge Gnabry | C18: X | E18: 1 | F18: 1 | G18: =MAX(0,IF(E18="",0,E18)-IF(F18="",0,F18)) -> 0
A19: GER17 | B19: Kai Havertz | C19: X | G19: =MAX(0,IF(E19="",0,E19)-IF(F19="",0,F19)) -> 0
A20: GER18 | B20: Leroy Sané | C20: X | G20: =MAX(0,IF(E20="",0,E20)-IF(F20="",0,F20)) -> 0
A21: GER19 | B21: Karim Adeyemi | C21: X | G21: =MAX(0,IF(E21="",0,E21)-IF(F21="",0,F21)) -> 0
A22: GER20 | B22: Nick Woltemade | C22: X | G22: =MAX(0,IF(E22="",0,E22)-IF(F22="",0,F22)) -> 0

Sheet GRUPO E · Curaçao
A1: GRUPO E · Curaçao
A2: Código | B2: Jugador / Cromo | C2: Tengo | D2: Pedir | E2: Repetidos | F2: Enviados | G2: Disponibles
A3: CUW1 | B3: Escudo | C3: X | G3: =MAX(0,IF(E3="",0,E3)-IF(F3="",0,F3)) -> 0
A4: CUW2 | B4: Eloy Room | C4: X | E4: 2 | F4: 2 | G4: =MAX(0,IF(E4="",0,E4)-IF(F4="",0,F4)) -> 0
A5: CUW3 | B5: Armando Obispo | C5: X | E5: 1 | F5: 1 | G5: =MAX(0,IF(E5="",0,E5)-IF(F5="",0,F5)) -> 0
A6: CUW4 | B6: Sherel Floranus | C6: X | E6: 1 | F6: 1 | G6: =MAX(0,IF(E6="",0,E6)-IF(F6="",0,F6)) -> 0
A7: CUW5 | B7: Jurien Gaari | C7: X | E7: 1 | F7: 1 | G7: =MAX(0,IF(E7="",0,E7)-IF(F7="",0,F7)) -> 0
A8: CUW6 | B8: Joshua Brenet | C8: X | G8: =MAX(0,IF(E8="",0,E8)-IF(F8="",0,F8)) -> 0
A9: CUW7 | B9: Roshon Van Eijma | C9: X | G9: =MAX(0,IF(E9="",0,E9)-IF(F9="",0,F9)) -> 0
A10: CUW8 | B10: Shurandy Sambo | C10: X | G10: =MAX(0,IF(E10="",0,E10)-IF(F10="",0,F10)) -> 0
A11: CUW9 | B11: Livano Comenencia | C11: X | E11: 2 | F11: 2 | G11: =MAX(0,IF(E11="",0,E11)-IF(F11="",0,F11)) -> 0
A12: CUW10 | B12: Godfried Roemeratoe | C12: X | E12: 1 | F12: 1 | G12: =MAX(0,IF(E12="",0,E12)-IF(F12="",0,F12)) -> 0
A13: CUW11 | B13: Juninho Bacuna | C13: X | E13: 2 | F13: 2 | G13: =MAX(0,IF(E13="",0,E13)-IF(F13="",0,F13)) -> 0
A14: CUW12 | B14: Leandro Bacuna | C14: X | E14: 1 | F14: 1 | G14: =MAX(0,IF(E14="",0,E14)-IF(F14="",0,F14)) -> 0
A15: CUW13 | B15: Foto Equipo | C15: X | G15: =MAX(0,IF(E15="",0,E15)-IF(F15="",0,F15)) -> 0
A16: CUW14 | B16: Tahith Chong | C16: X | E16: 1 | F16: 1 | G16: =MAX(0,IF(E16="",0,E16)-IF(F16="",0,F16)) -> 0
A17: CUW15 | B17: Kenji Gorré | C17: X | E17: 1 | F17: 1 | G17: =MAX(0,IF(E17="",0,E17)-IF(F17="",0,F17)) -> 0
A18: CUW16 | B18: Jearl Margaritha | C18: X | E18: 2 | F18: 2 | G18: =MAX(0,IF(E18="",0,E18)-IF(F18="",0,F18)) -> 0
A19: CUW17 | B19: Jürgen Locadia | C19: X | G19: =MAX(0,IF(E19="",0,E19)-IF(F19="",0,F19)) -> 0
A20: CUW18 | B20: Jeremy Antonisse | C20: X | G20: =MAX(0,IF(E20="",0,E20)-IF(F20="",0,F20)) -> 0
A21: CUW19 | B21: Gervane Kastaneer | C21: X | E21: 1 | F21: 1 | G21: =MAX(0,IF(E21="",0,E21)-IF(F21="",0,F21)) -> 0
A22: CUW20 | B22: Sontje Hansen | C22: X | G22: =MAX(0,IF(E22="",0,E22)-IF(F22="",0,F22)) -> 0

Sheet GRUPO E · Cote dIvoire
A1: GRUPO E · Côte d'Ivoire
A2: Código | B2: Jugador / Cromo | C2: Tengo | D2: Pedir | E2: Repetidos | F2: Enviados | G2: Disponibles
A3: CIV1 | B3: Escudo | C3: X | E3: 1 | F3: 1 | G3: =MAX(0,IF(E3="",0,E3)-IF(F3="",0,F3)) -> 0
A4: CIV2 | B4: Yahia Fofana | C4: X | E4: 1 | F4: 1 | G4: =MAX(0,IF(E4="",0,E4)-IF(F4="",0,F4)) -> 0
A5: CIV3 | B5: Ghislain Konan | C5: X | G5: =MAX(0,IF(E5="",0,E5)-IF(F5="",0,F5)) -> 0
A6: CIV4 | B6: Wilfried Singo | C6: X | G6: =MAX(0,IF(E6="",0,E6)-IF(F6="",0,F6)) -> 0
A7: CIV5 | B7: Odilon Kossounou | C7: X | G7: =MAX(0,IF(E7="",0,E7)-IF(F7="",0,F7)) -> 0
A8: CIV6 | B8: Evan Ndicka | C8: X | E8: 2 | F8: 2 | G8: =MAX(0,IF(E8="",0,E8)-IF(F8="",0,F8)) -> 0
A9: CIV7 | B9: Willy Boly | C9: X | E9: 2 | F9: 2 | G9: =MAX(0,IF(E9="",0,E9)-IF(F9="",0,F9)) -> 0
A10: CIV8 | B10: Emmanuel Agbadou | C10: X | G10: =MAX(0,IF(E10="",0,E10)-IF(F10="",0,F10)) -> 0
A11: CIV9 | B11: Ousmane Diomande | C11: X | G11: =MAX(0,IF(E11="",0,E11)-IF(F11="",0,F11)) -> 0
A12: CIV10 | B12: Franck Kessié | C12: X | G12: =MAX(0,IF(E12="",0,E12)-IF(F12="",0,F12)) -> 0
A13: CIV11 | B13: Seko Fofana | C13: X | E13: 4 | F13: 4 | G13: =MAX(0,IF(E13="",0,E13)-IF(F13="",0,F13)) -> 0
A14: CIV12 | B14: Ibrahim Sangaré | C14: X | E14: 1 | F14: 1 | G14: =MAX(0,IF(E14="",0,E14)-IF(F14="",0,F14)) -> 0
A15: CIV13 | B15: Foto Equipo | C15: X | E15: 1 | F15: 1 | G15: =MAX(0,IF(E15="",0,E15)-IF(F15="",0,F15)) -> 0
A16: CIV14 | B16: Jean-Philippe Gbamin | C16: X | E16: 1 | F16: 1 | G16: =MAX(0,IF(E16="",0,E16)-IF(F16="",0,F16)) -> 0
A17: CIV15 | B17: Amad Diallo | C17: X | G17: =MAX(0,IF(E17="",0,E17)-IF(F17="",0,F17)) -> 0
A18: CIV16 | B18: Sébastien Haller | C18: X | G18: =MAX(0,IF(E18="",0,E18)-IF(F18="",0,F18)) -> 0
A19: CIV17 | B19: Simon Adingra | C19: X | G19: =MAX(0,IF(E19="",0,E19)-IF(F19="",0,F19)) -> 0
A20: CIV18 | B20: Yan Diomande | C20: X | E20: 2 | F20: 2 | G20: =MAX(0,IF(E20="",0,E20)-IF(F20="",0,F20)) -> 0
A21: CIV19 | B21: Evann Guessand | C21: X | E21: 2 | F21: 2 | G21: =MAX(0,IF(E21="",0,E21)-IF(F21="",0,F21)) -> 0
A22: CIV20 | B22: Oumar Diakité | C22: X | E22: 1 | F22: 1 | G22: =MAX(0,IF(E22="",0,E22)-IF(F22="",0,F22)) -> 0

Sheet GRUPO E · Ecuador
A1: GRUPO E · Ecuador
A2: Código | B2: Jugador / Cromo | C2: Tengo | D2: Pedir | E2: Repetidos | F2: Enviados | G2: Disponibles
A3: ECU1 | B3: Escudo | C3: X | E3: 1 | F3: 1 | G3: =MAX(0,IF(E3="",0,E3)-IF(F3="",0,F3)) -> 0
A4: ECU2 | B4: Hernán Galíndez | C4: X | E4: 3 | F4: 3 | G4: =MAX(0,IF(E4="",0,E4)-IF(F4="",0,F4)) -> 0
A5: ECU3 | B5: Gonzalo Valle | C5: X | E5: 2 | F5: 2 | G5: =MAX(0,IF(E5="",0,E5)-IF(F5="",0,F5)) -> 0
A6: ECU4 | B6: Piero Hincapié | C6: X | G6: =MAX(0,IF(E6="",0,E6)-IF(F6="",0,F6)) -> 0
A7: ECU5 | B7: Pervis Estupiñán | C7: X | E7: 1 | F7: 1 | G7: =MAX(0,IF(E7="",0,E7)-IF(F7="",0,F7)) -> 0
A8: ECU6 | B8: Willian Pacho | C8: X | G8: =MAX(0,IF(E8="",0,E8)-IF(F8="",0,F8)) -> 0
A9: ECU7 | B9: Ángelo Preciado | C9: X | G9: =MAX(0,IF(E9="",0,E9)-IF(F9="",0,F9)) -> 0
A10: ECU8 | B10: Joel Ordóñez | C10: X | E10: 1 | F10: 1 | G10: =MAX(0,IF(E10="",0,E10)-IF(F10="",0,F10)) -> 0
A11: ECU9 | B11: Moisés Caicedo | C11: X | G11: =MAX(0,IF(E11="",0,E11)-IF(F11="",0,F11)) -> 0
A12: ECU10 | B12: Alan Franco | C12: X | E12: 2 | F12: 2 | G12: =MAX(0,IF(E12="",0,E12)-IF(F12="",0,F12)) -> 0
A13: ECU11 | B13: Kendry Páez | C13: X | G13: =MAX(0,IF(E13="",0,E13)-IF(F13="",0,F13)) -> 0
A14: ECU12 | B14: Pedro Vite | C14: X | E14: 1 | F14: 1 | G14: =MAX(0,IF(E14="",0,E14)-IF(F14="",0,F14)) -> 0
A15: ECU13 | B15: Foto Equipo | C15: X | E15: 1 | F15: 1 | G15: =MAX(0,IF(E15="",0,E15)-IF(F15="",0,F15)) -> 0
A16: ECU14 | B16: John Yeboah | C16: X | E16: 1 | F16: 1 | G16: =MAX(0,IF(E16="",0,E16)-IF(F16="",0,F16)) -> 0
A17: ECU15 | B17: Leonardo Campana | C17: X | E17: 1 | F17: 1 | G17: =MAX(0,IF(E17="",0,E17)-IF(F17="",0,F17)) -> 0
A18: ECU16 | B18: Gonzalo Plata | C18: X | G18: =MAX(0,IF(E18="",0,E18)-IF(F18="",0,F18)) -> 0
A19: ECU17 | B19: Nilson Angulo | C19: X | E19: 2 | F19: 2 | G19: =MAX(0,IF(E19="",0,E19)-IF(F19="",0,F19)) -> 0
A20: ECU18 | B20: Alan Minda | C20: X | G20: =MAX(0,IF(E20="",0,E20)-IF(F20="",0,F20)) -> 0
A21: ECU19 | B21: Kevin Rodríguez | C21: X | E21: 2 | F21: 2 | G21: =MAX(0,IF(E21="",0,E21)-IF(F21="",0,F21)) -> 0
A22: ECU20 | B22: Enner Valencia | C22: X | E22: 2 | F22: 2 | G22: =MAX(0,IF(E22="",0,E22)-IF(F22="",0,F22)) -> 0

Sheet GRUPO F · Netherlands
A1: GRUPO F · Netherlands
A2: Código | B2: Jugador / Cromo | C2: Tengo | D2: Pedir | E2: Repetidos | F2: Enviados | G2: Disponibles
A3: NED1 | B3: Escudo | C3: X | E3: 1 | F3: 1 | G3: =MAX(0,IF(E3="",0,E3)-IF(F3="",0,F3)) -> 0
A4: NED2 | B4: Bart Verbruggen | C4: X | E4: 1 | F4: 1 | G4: =MAX(0,IF(E4="",0,E4)-IF(F4="",0,F4)) -> 0
A5: NED3 | B5: Virgil van Dijk | C5: X | E5: 1 | F5: 1 | G5: =MAX(0,IF(E5="",0,E5)-IF(F5="",0,F5)) -> 0
A6: NED4 | B6: Micky van de Ven | C6: X | E6: 1 | F6: 1 | G6: =MAX(0,IF(E6="",0,E6)-IF(F6="",0,F6)) -> 0
A7: NED5 | B7: Jurrien Timber | C7: X | E7: 1 | F7: 1 | G7: =MAX(0,IF(E7="",0,E7)-IF(F7="",0,F7)) -> 0
A8: NED6 | B8: Denzel Dumfries | C8: X | G8: =MAX(0,IF(E8="",0,E8)-IF(F8="",0,F8)) -> 0
A9: NED7 | B9: Nathan Aké | C9: X | E9: 5 | F9: 5 | G9: =MAX(0,IF(E9="",0,E9)-IF(F9="",0,F9)) -> 0
A10: NED8 | B10: Jeremie Frimpong | C10: X | G10: =MAX(0,IF(E10="",0,E10)-IF(F10="",0,F10)) -> 0
A11: NED9 | B11: Jan Paul van Hecke | C11: X | G11: =MAX(0,IF(E11="",0,E11)-IF(F11="",0,F11)) -> 0
A12: NED10 | B12: Tijjani Reijnders | C12: X | G12: =MAX(0,IF(E12="",0,E12)-IF(F12="",0,F12)) -> 0
A13: NED11 | B13: Ryan Gravenberch | C13: X | G13: =MAX(0,IF(E13="",0,E13)-IF(F13="",0,F13)) -> 0
A14: NED12 | B14: Teun Koopmeiners | C14: X | E14: 1 | F14: 1 | G14: =MAX(0,IF(E14="",0,E14)-IF(F14="",0,F14)) -> 0
A15: NED13 | B15: Foto Equipo | C15: X | E15: 1 | F15: 1 | G15: =MAX(0,IF(E15="",0,E15)-IF(F15="",0,F15)) -> 0
A16: NED14 | B16: Frenkie de Jong | C16: X | E16: 1 | F16: 1 | G16: =MAX(0,IF(E16="",0,E16)-IF(F16="",0,F16)) -> 0
A17: NED15 | B17: Xavi Simons | C17: X | G17: =MAX(0,IF(E17="",0,E17)-IF(F17="",0,F17)) -> 0
A18: NED16 | B18: Justin Kluivert | C18: X | G18: =MAX(0,IF(E18="",0,E18)-IF(F18="",0,F18)) -> 0
A19: NED17 | B19: Memphis Depay | C19: X | E19: 1 | F19: 1 | G19: =MAX(0,IF(E19="",0,E19)-IF(F19="",0,F19)) -> 0
A20: NED18 | B20: Donyell Malen | C20: X | G20: =MAX(0,IF(E20="",0,E20)-IF(F20="",0,F20)) -> 0
A21: NED19 | B21: Wout Weghorst | C21: X | E21: 1 | F21: 1 | G21: =MAX(0,IF(E21="",0,E21)-IF(F21="",0,F21)) -> 0
A22: NED20 | B22: Cody Gakpo | C22: X | G22: =MAX(0,IF(E22="",0,E22)-IF(F22="",0,F22)) -> 0

Sheet GRUPO F · Japan
A1: GRUPO F · Japan
A2: Código | B2: Jugador / Cromo | C2: Tengo | D2: Pedir | E2: Repetidos | F2: Enviados | G2: Disponibles
A3: JPN1 | B3: Escudo | C3: X | E3: 1 | F3: 1 | G3: =MAX(0,IF(E3="",0,E3)-IF(F3="",0,F3)) -> 0
A4: JPN2 | B4: Zion Suzuki | C4: X | G4: =MAX(0,IF(E4="",0,E4)-IF(F4="",0,F4)) -> 0
A5: JPN3 | B5: Henry Heroki Mochizuki | C5: X | G5: =MAX(0,IF(E5="",0,E5)-IF(F5="",0,F5)) -> 0
A6: JPN4 | B6: Ayumu Seko | C6: X | G6: =MAX(0,IF(E6="",0,E6)-IF(F6="",0,F6)) -> 0
A7: JPN5 | B7: Junnosuke Suzuki | C7: X | G7: =MAX(0,IF(E7="",0,E7)-IF(F7="",0,F7)) -> 0
A8: JPN6 | B8: Shogo Taniguchi | C8: X | E8: 2 | F8: 2 | G8: =MAX(0,IF(E8="",0,E8)-IF(F8="",0,F8)) -> 0
A9: JPN7 | B9: Tsuyoshi Watanabe | C9: X | E9: 1 | F9: 1 | G9: =MAX(0,IF(E9="",0,E9)-IF(F9="",0,F9)) -> 0
A10: JPN8 | B10: Kaishu Sano | C10: X | E10: 2 | F10: 2 | G10: =MAX(0,IF(E10="",0,E10)-IF(F10="",0,F10)) -> 0
A11: JPN9 | B11: Yuki Soma | C11: X | G11: =MAX(0,IF(E11="",0,E11)-IF(F11="",0,F11)) -> 0
A12: JPN10 | B12: Ao Tanaka | C12: X | E12: 1 | F12: 1 | G12: =MAX(0,IF(E12="",0,E12)-IF(F12="",0,F12)) -> 0
A13: JPN11 | B13: Daichi Kamada | C13: X | E13: 1 | F13: 1 | G13: =MAX(0,IF(E13="",0,E13)-IF(F13="",0,F13)) -> 0
